Workbook

Sheet Master Data
C2: Flip 7 Best Strat Test Data
C3: First set of strategies Tested:
D5: Average Rounds to 200 | E5: Average Bust Rounds | F5: Average Successful Rounds | G5: Average Score | H5: Is done?
C6: Human (Without Probability) | D6: ='Human No Prob'!T13 -> 9.5 | E6: ='Human No Prob'!U13 -> 4 | F6: ='Human No Prob'!V13 -> 5.5 | G6: ='Human No Prob'!W13 -> 37.773333
C7: Human (With Probability) | D7: ='Human Prob'!T13 -> 9.3 | E7: ='Human Prob'!U13 -> 3.2 | F7: ='Human Prob'!V13 -> 6.1 | G7: ='Human Prob'!W13 -> 34.860952
C8: Always Bank (2 Cards) | D8: ='2 Card Bank'!Y13 -> 13.1 | E8: ='2 Card Bank'!Z13 -> 1.6 | F8: ='2 Card Bank'!AA13 -> 11.5 | G8: ='2 Card Bank'!AB13 -> 18.125671
C9: Always Bank (3 Cards) | D9: ='3 Card Bank'!T13 -> 10.9 | E9: ='3 Card Bank'!U13 -> 2.7 | F9: ='3 Card Bank'!V13 -> 8.2 | G9: ='3 Card Bank'!W13 -> 26.262897
C10: Always Bank (4 Cards) | D10: ='4 Card Bank'!Y13 -> 11.6 | E10: ='4 Card Bank'!Z13 -> 5.3 | F10: ='4 Card Bank'!AA13 -> 6.3 | G10: ='4 Card Bank'!AB13 -> 33.85
C11: Always Flip 7 | D11: ='Flip7 or Bust'!T13 -> 0 | E11: ='Flip7 or Bust'!U13 -> 0 | F11: ='Flip7 or Bust'!V13 -> 0 | G11: ='Flip7 or Bust'!W13 -> #DIV/0!
C12: Always Bank (Score of 20+) | D12: ='Score 20 Bank'!T13 -> 10.6 | E12: ='Score 20 Bank'!U13 -> 1.7 | F12: ='Score 20 Bank'!V13 -> 8.9 | G12: ='Score 20 Bank'!W13 -> 24.0375
C13: Always Bank (Score of 25+) | D13: ='Score 25 Bank'!T13 -> 10.6 | E13: ='Score 25 Bank'!U13 -> 3.5 | F13: ='Score 25 Bank'!V13 -> 7.1 | G13: ='Score 25 Bank'!W13 -> 29.678571
C14: Always Bank (Score of 30+) | D14: ='Score 30 Bank'!T13 -> 9.3 | E14: ='Score 30 Bank'!U13 -> 2.9 | F14: ='Score 30 Bank'!V13 -> 6.4 | G14: ='Score 30 Bank'!W13 -> 34.114286
C15: Always Bank (Score of 35+) | D15: ='Score 35 Bank'!Y13 -> 11.7 | E15: ='Score 35 Bank'!Z13 -> 6.3 | F15: ='Score 35 Bank'!AA13 -> 5.4 | G15: ='Score 35 Bank'!AB13 -> 40.326667
C16: Always Bank (Score of 40+) | D16: ='Score 40 Bank'!AI13 -> 12.4 | E16: ='Score 40 Bank'!AJ13 -> 7.4 | F16: ='Score 40 Bank'!AK13 -> 5 | G16: ='Score 40 Bank'!AL13 -> 44.36
C17: Always Bank (Cumulative 70%) | D17: ='Cumulative Odds 70%'!Y13 -> 11 | E17: ='Cumulative Odds 70%'!Z13 -> 2.7 | F17: ='Cumulative Odds 70%'!AA13 -> 8.3 | G17: ='Cumulative Odds 70%'!AB13 -> 25.304167
C18: Always Bank (Cumulative 60%) | D18: ='Cumulative Odds 60%'!T13 -> 10.9 | E18: ='Cumulative Odds 60%'!U13 -> 3.9 | F18: ='Cumulative Odds 60%'!V13 -> 7 | G18: ='Cumulative Odds 60%'!W13 -> 30.782738 | N18: Cards flipped | O18: 1 | P18: 2 | Q18: 3 | R18: 4 | S18: 5 | T18: 6 | U18: 7 | V18: 8 | W18: 9 | X18: 10 | Y18: 11 | Z18: 12 | AA18: 13 | AB18: 14 | AC18: 15 | AD18: 16 | AE18: 17 | AF18: 18 | AG18: 19 | AH18: 20 | AI18: 21 | AJ18: 22 | AK18: 23 | AL18: 24 | AM18: 25 | AN18: 26 | AO18: 27 | AP18: 28 | AQ18: 29 | AR18: 30 | AS18: 31 | AT18: 32 | AU18: 33 | AV18: 34 | AW18: 35 | AX18: 36 | AY18: 37 | AZ18: 38 | BA18: 39 | BB18: 40 | BC18: 41 | BD18: 42 | BE18: 43 | BF18: 44 | BG18: 45 | BH18: 46 | BI18: 47 | BJ18: 48 | BK18: 49 | BL18: 50 | BM18: 51 | BN18: 52 | BO18: 53 | BP18: 54 | BQ18: 55 | BR18: 56 | BS18: 57 | BT18: 58 | BU18: 59 | BV18: 60 | BW18: 61 | BX18: 62 | BY18: 63 | BZ18: 64 | CA18: 65 | CB18: 66 | CC18: 67 | CD18: 68 | CE18: 69 | CF18: 70 | CG18: 71 | CH18: 72 | CI18: 73 | CJ18: 74 | CK18: 75 | CL18: 76 | CM18: 77 | CN18: 78 | CO18: 79 | CP18: 80 | CQ18: 81 | CR18: 82 | CS18: 83
C19: Always Bank (Cumulative 50%) | D19: ='Cumulative Odds 50%'!Y13 -> 11.3 | E19: ='Cumulative Odds 50%'!Z13 -> 5.1 | F19: ='Cumulative Odds 50%'!AA13 -> 6.2 | G19: ='Cumulative Odds 50%'!AB13 -> 35.230952 | N19: Differential as a percent | O19: -0.087912088 | P19: -0.22222222 | Q19: -0.46067416 | R19: 0.5 | S19: -0.42528736 | T19: -0.3255814 | U19: 0.66666667 | V19: 1.5180723 | W19: 1.1707317 | X19: 2.9012346 | Y19: 1.75 | Z19: -0.82051282 | AA19: 12.012987 | AB19: 11.315789 | AC19: 12.666667 | AD19: 12.27027 | AE19: 12.863014 | AF19: 2.7746479 | AG19: 3.5714286 | AH19: 3.3623188 | AI19: 2.7058824 | AJ19: 2.2089552 | AK19: 0.51515152 | AL19: 5.4848485 | AM19: 6.2307692 | AN19: 5.5625 | AO19: 5.4920635 | AP19: 1.3870968 | AQ19: -0.66666667 | AR19: 2.7457627 | AS19: 2.4137931 | AT19: 0.42857143 | AU19: 0.90909091 | AV19: 1.4814815 | AW19: 6.245283 | AX19: 6.1538462 | AY19: -1 | AZ19: 0.63265306 | BA19: -18.75 | BB19: -21.276596 | BC19: -30.434783 | BD19: -33.333333 | BE19: 7 | BF19: 5.7142857 | BG19: 4.1707317 | BH19: 2.7435897 | BI19: 1.3157895 | BJ19: 0.86486486 | BK19: 2.3333333 | BL19: 7.1428571 | BM19: 3 | BN19: -1.375 | BO19: 0.6451612903225801, | BP19: 1 | BQ19: 2.6206897 | BR19: -1.1111111 | BS19: -4.2307692 | BT19: -3.5527137e-15 | BU19: 0.83333333 | BV19: -0.7826087 | BW19: 0.23809524 | BX19: 3 | BY19: -20.105263 | BZ19: -14.529412 | CA19: -4.3333333 | CB19: 0.57142857 | CC19: 2.9230769 | CD19: -3.6666667 | CE19: 0 | CF19: -0.22222222 | CG19: -4.5 | CH19: 12 | CI19: 23 | CJ19: 31 | CK19: 40 | CL19: 53 | CM19: 58 | CN19: 0.11111111 | CO19: 0.39325843 | CP19: 0 | CQ19: 0.51162791 | CR19: 1.0588235 | CS19: 1.5238095
C20: Always Bank (Cumulative 40%) | D20: ='Cumulative Odds 40%'!Y13 -> 11.9 | E20: ='Cumulative Odds 40%'!Z13 -> 6.4 | F20: ='Cumulative Odds 40%'!AA13 -> 5.5 | G20: ='Cumulative Odds 40%'!AB13 -> 40.42
C21: Always Bank (Cumulative 30%) | D21: ='Cumulative Odds 30%'!Y13 -> 10.4 | E21: ='Cumulative Odds 30%'!Z13 -> 5.5 | F21: ='Cumulative Odds 30%'!AA13 -> 4.9 | G21: ='Cumulative Odds 30%'!AB13 -> 44.345
C22: Always Bank (Individual 10%) | D22: ='Individual Odds 10%'!Y13 -> 14.5 | E22: ='Individual Odds 10%'!Z13 -> 0.6 | F22: ='Individual Odds 10%'!AA13 -> 13.9 | G22: ='Individual Odds 10%'!AB13 -> 15.143132
C23: Always Bank (Individual 20%) | D23: ='Individual Odds 20%'!T13 -> 10.5 | E23: ='Individual Odds 20%'!U13 -> 2.3 | F23: ='Individual Odds 20%'!V13 -> 8.2 | G23: ='Individual Odds 20%'!W13 -> 26.147222
C24: Always Bank (Individual 30%) | D24: ='Individual Odds 30%'!T13 -> 10.4 | E24: ='Individual Odds 30%'!U13 -> 4.1 | F24: ='Individual Odds 30%'!V13 -> 6.3 | G24: ='Individual Odds 30%'!W13 -> 35.610476
C25: Always Bank (Individual 40%) | D25: ='Individual Odds 40%'!Y13 -> 13.1 | E25: ='Individual Odds 40%'!Z13 -> 8.3 | F25: ='Individual Odds 40%'!AA13 -> 4.8 | G25: ='Individual Odds 40%'!AB13 -> 47.795
AG26: 28.846154
C27: Conclusions: | J27: Testing Heuristics | AG27: 28.846154
C28: The Score 30+ and Probability 30 both yielded promising results. My personal strategy is a close combination of the 2 and leads me to believe there is likely a scorea round 27-32 that’s optimal and that there's a probability that’s best too. The probability is held back by the fact that the human players of the game have no idea of the active probability as it changes as more cards are dealt. I did notice through my testing however that scores closely resembled the probability that was held +/- about 3. So for my second round of testing I want to test the new more spefic score values, probability values, a combined strategy that only banks once either condition is met and a heuristical approach to the probabily that uses a simple calculation that a regular person could do to understand tehir bust chances. This therefore is what I will strive to achieve in my second set of strategy testing.
K29: ()
K30: Test 1 | L30: Test 2 | O30: Cards Flipped
K31: -0.087912088 | L31: 1 | O31: 1
K32: -0.22222222 | L32: 1.8888889 | O32: 2
K33: -0.46067416 | L33: 1.7640449 | O33: 3
K34: 0.5 | L34: 1.1363636 | O34: 4
K35: -0.42528736 | L35: -1.027907 | O35: 5
K36: -0.3255814 | L36: -0.047058824 | O36: 6
K37: 0.66666667 | L37: -0.78095238 | O37: 7
K38: 1.5180723 | L38: -1.3638554 | O38: 8
K39: 1.1707317 | L39: -1.9609756 | O39: 9
K40: 2.9012346 | L40: -1.05 | O40: 10
K41: 1.75 | L41: -1.1924051 | O41: 11
K42: -0.82051282 | L42: -0.31282051 | O42: 12
...

Sheet Human No Prob
B2: Human No Probability | D2: Round 1 | E2: Round 2 | F2: Round 3 | G2: Round 4 | H2: Round 5 | I2: Round 6 | J2: Round 7 | K2: Round 8 | L2: Round 9 | M2: Round 10 | N2: Round 11 | O2: Round 12 | P2: Round 13 | Q2: Round 14 | R2: Round 15 | S2: Total | T2: Total Rounds | U2: Total Busts | V2: Successes | W2: Average Score
C3: Game 1 | D3: 0 | E3: 0 | F3: 0 | G3: 0 | H3: 34 | I3: 0 | J3: 38 | K3: 29 | L3: 0 | M3: 40 | N3: 0 | O3: 60 | S3: =SUM(D3:R3) -> 201 | T3: =COUNT(D3:R3) -> 12 | U3: =COUNTIF(D3:R3,0) -> 7 | V3: =T3-U3 -> 5 | W3: =S3/V3 -> 40.2
C4: Game 2 | D4: 0 | E4: 42 | F4: 0 | G4: 37 | H4: 61 | I4: 29 | J4: 0 | K4: 34 | S4: =SUM(D4:R4) -> 203 | T4: =COUNT(D4:R4) -> 8 | U4: =COUNTIF(D4:R4,0) -> 3 | V4: =T4-U4 -> 5 | W4: =S4/V4 -> 40.6
C5: Game 3 | D5: 0 | E5: 48 | F5: 0 | G5: 0 | H5: 38 | I5: 29 | J5: 0 | K5: 0 | L5: 34 | M5: 64 | S5: =SUM(D5:R5) -> 213 | T5: =COUNT(D5:R5) -> 10 | U5: =COUNTIF(D5:R5,0) -> 5 | V5: =T5-U5 -> 5 | W5: =S5/V5 -> 42.6
C6: Game 4 | D6: 34 | E6: 27 | F6: 0 | G6: 0 | H6: 0 | I6: 29 | J6: 0 | K6: 0 | L6: 40 | M6: 35 | N6: 61 | S6: =SUM(D6:R6) -> 226 | T6: =COUNT(D6:R6) -> 11 | U6: =COUNTIF(D6:R6,0) -> 5 | V6: =T6-U6 -> 6 | W6: =S6/V6 -> 37.666667
C7: Game 5 | D7: 30 | E7: 0 | F7: 34 | G7: 36 | H7: 0 | I7: 38 | J7: 31 | K7: 34 | S7: =SUM(D7:R7) -> 203 | T7: =COUNT(D7:R7) -> 8 | U7: =COUNTIF(D7:R7,0) -> 2 | V7: =T7-U7 -> 6 | W7: =S7/V7 -> 33.833333
C8: Game 6 | D8: 0 | E8: 33 | F8: 31 | G8: 32 | H8: 38 | I8: 31 | J8: 37 | S8: =SUM(D8:R8) -> 202 | T8: =COUNT(D8:R8) -> 7 | U8: =COUNTIF(D8:R8,0) -> 1 | V8: =T8-U8 -> 6 | W8: =S8/V8 -> 33.666667
C9: Game 7 | D9: 0 | E9: 0 | F9: 29 | G9: 41 | H9: 0 | I9: 0 | J9: 38 | K9: 0 | L9: 0 | M9: 38 | N9: 32 | O9: 33 | S9: =SUM(D9:R9) -> 211 | T9: =COUNT(D9:R9) -> 12 | U9: =COUNTIF(D9:R9,0) -> 6 | V9: =T9-U9 -> 6 | W9: =S9/V9 -> 35.166667
C10: Game 8 | D10: 38 | E10: 31 | F10: 0 | G10: 64 | H10: 0 | I10: 40 | J10: 0 | K10: 27 | S10: =SUM(D10:R10) -> 200 | T10: =COUNT(D10:R10) -> 8 | U10: =COUNTIF(D10:R10,0) -> 3 | V10: =T10-U10 -> 5 | W10: =S10/V10 -> 40
C11: Game 9 | D11: 30 | E11: 0 | F11: 0 | G11: 0 | H11: 0 | I11: 40 | J11: 23 | K11: 32 | L11: 0 | M11: 33 | N11: 0 | O11: 46 | S11: =SUM(D11:R11) -> 204 | T11: =COUNT(D11:R11) -> 12 | U11: =COUNTIF(D11:R11,0) -> 6 | V11: =T11-U11 -> 6 | W11: =S11/V11 -> 34
C12: Game 10 | D12: 0 | E12: 71 | F12: 35 | G12: 0 | H12: 28 | I12: 28 | J12: 38 | S12: =SUM(D12:R12) -> 200 | T12: =COUNT(D12:R12) -> 7 | U12: =COUNTIF(D12:R12,0) -> 2 | V12: =T12-U12 -> 5 | W12: =S12/V12 -> 40
S13: Averages: | T13: =AVERAGE(T3:T12) -> 9.5 | U13: =AVERAGE(U3:U12) -> 4 | V13: =AVERAGE(V3:V12) -> 5.5 | W13: =AVERAGE(W3:W12) -> 37.773333

Sheet Human Prob
B2: Human With Probability | D2: Round 1 | E2: Round 2 | F2: Round 3 | G2: Round 4 | H2: Round 5 | I2: Round 6 | J2: Round 7 | K2: Round 8 | L2: Round 9 | M2: Round 10 | N2: Round 11 | O2: Round 12 | P2: Round 13 | Q2: Round 14 | R2: Round 15 | S2: Total | T2: Total Rounds | U2: Total Busts | V2: Successes | W2: Average Score
C3: Game 1 | D3: 0 | E3: 40 | F3: 0 | G3: 62 | H3: 68 | I3: 0 | J3: 0 | K3: 0 | L3: 0 | M3: 36 | S3: =SUM(D3:R3) -> 206 | T3: =COUNT(D3:R3) -> 10 | U3: =COUNTIF(D3:R3,0) -> 6 | V3: =T3-U3 -> 4 | W3: =S3/V3 -> 51.5
C4: Game 2 | D4: 0 | E4: 0 | F4: 0 | G4: 0 | H4: 36 | I4: 30 | J4: 0 | K4: 0 | L4: 35 | M4: 33 | N4: 0 | O4: 37 | P4: 33 | S4: =SUM(D4:R4) -> 204 | T4: =COUNT(D4:R4) -> 13 | U4: =COUNTIF(D4:R4,0) -> 7 | V4: =T4-U4 -> 6 | W4: =S4/V4 -> 34
C5: Game 3 | D5: 0 | E5: 0 | F5: 27 | G5: 34 | H5: 32 | I5: 42 | J5: 35 | K5: 35 | S5: =SUM(D5:R5) -> 205 | T5: =COUNT(D5:R5) -> 8 | U5: =COUNTIF(D5:R5,0) -> 2 | V5: =T5-U5 -> 6 | W5: =S5/V5 -> 34.166667
C6: Game 4 | D6: 26 | E6: 39 | F6: 28 | G6: 0 | H6: 0 | I6: 36 | J6: 22 | K6: 30 | L6: 30 | S6: =SUM(D6:R6) -> 211 | T6: =COUNT(D6:R6) -> 9 | U6: =COUNTIF(D6:R6,0) -> 2 | V6: =T6-U6 -> 7 | W6: =S6/V6 -> 30.142857
C7: Game 5 | D7: 31 | E7: 0 | F7: 0 | G7: 33 | H7: 29 | I7: 0 | J7: 28 | K7: 31 | L7: 34 | M7: 21 | S7: =SUM(D7:R7) -> 207 | T7: =COUNT(D7:R7) -> 10 | U7: =COUNTIF(D7:R7,0) -> 3 | V7: =T7-U7 -> 7 | W7: =S7/V7 -> 29.571429
C8: Game 6 | D8: 34 | E8: 33 | F8: 30 | G8: 34 | H8: 21 | I8: 0 | J8: 33 | K8: 24 | S8: =SUM(D8:R8) -> 209 | T8: =COUNT(D8:R8) -> 8 | U8: =COUNTIF(D8:R8,0) -> 1 | V8: =T8-U8 -> 7 | W8: =S8/V8 -> 29.857143
C9: Game 7 | D9: 0 | E9: 0 | F9: 26 | G9: 31 | H9: 0 | I9: 30 | J9: 27 | K9: 36 | L9: 26 | M9: 31 | S9: =SUM(D9:R9) -> 207 | T9: =COUNT(D9:R9) -> 10 | U9: =COUNTIF(D9:R9,0) -> 3 | V9: =T9-U9 -> 7 | W9: =S9/V9 -> 29.571429
C10: Game 8 | D10: 34 | E10: 38 | F10: 43 | G10: 0 | H10: 0 | I10: 40 | J10: 28 | K10: 0 | L10: 17 | S10: =SUM(D10:R10) -> 200 | T10: =COUNT(D10:R10) -> 9 | U10: =COUNTIF(D10:R10,0) -> 3 | V10: =T10-U10 -> 6 | W10: =S10/V10 -> 33.333333
C11: Game 9 | D11: 38 | E11: 38 | F11: 24 | G11: 0 | H11: 63 | I11: 0 | J11: 0 | K11: 46 | S11: =SUM(D11:R11) -> 209 | T11: =COUNT(D11:R11) -> 8 | U11: =COUNTIF(D11:R11,0) -> 3 | V11: =T11-U11 -> 5 | W11: =S11/V11 -> 41.8
C12: Game 10 | D12: 34 | E12: 0 | F12: 39 | G12: 46 | H12: 24 | I12: 0 | J12: 40 | K12: 25 | S12: =SUM(D12:R12) -> 208 | T12: =COUNT(D12:R12) -> 8 | U12: =COUNTIF(D12:R12,0) -> 2 | V12: =T12-U12 -> 6 | W12: =S12/V12 -> 34.666667
S13: Averages: | T13: =AVERAGE(T3:T12) -> 9.3 | U13: =AVERAGE(U3:U12) -> 3.2 | V13: =AVERAGE(V3:V12) -> 6.1 | W13: =AVERAGE(W3:W12) -> 34.860952

Sheet 2 Card Bank
B2: Always Bank 2 Cards | D2: Round 1 | E2: Round 2 | F2: Round 3 | G2: Round 4 | H2: Round 5 | I2: Round 6 | J2: Round 7 | K2: Round 8 | L2: Round 9 | M2: Round 10 | N2: Round 11 | O2: Round 12 | P2: Round 13 | Q2: Round 14 | R2: Round 15 | S2: Round 16 | T2: Round 17 | U2: Round 18 | V2: Round 19 | W2: Round 20 | X2: Total | Y2: Total Rounds | Z2: Total Busts | AA2: Successes | AB2: Average Score
C3: Game 1 | D3: 21 | E3: 21 | F3: 11 | G3: 17 | H3: 24 | I3: 19 | J3: 24 | K3: 18 | L3: 17 | M3: 19 | N3: 21 | X3: =SUM(D3:W3) -> 212 | Y3: =COUNT(D3:W3) -> 11 | Z3: =COUNTIF(D3:W3,0) -> 0 | AA3: =Y3-Z3 -> 11 | AB3: =X3/AA3 -> 19.272727
C4: Game 2 | D4: 0 | E4: 16 | F4: 15 | G4: 19 | H4: 15 | I4: 17 | J4: 23 | K4: 7 | L4: 7 | M4: 14 | N4: 15 | O4: 6 | P4: 17 | Q4: 16 | R4: 19 | X4: =SUM(D4:W4) -> 206 | Y4: =COUNT(D4:W4) -> 15 | Z4: =COUNTIF(D4:W4,0) -> 1 | AA4: =Y4-Z4 -> 14 | AB4: =X4/AA4 -> 14.714286
C5: Game 3 | D5: 24 | E5: 19 | F5: 20 | G5: 17 | H5: 21 | I5: 0 | J5: 21 | K5: 22 | L5: 14 | M5: 21 | N5: 21 | X5: =SUM(D5:W5) -> 200 | Y5: =COUNT(D5:W5) -> 11 | Z5: =COUNTIF(D5:W5,0) -> 1 | AA5: =Y5-Z5 -> 10 | AB5: =X5/AA5 -> 20
C6: Game 4 | D6: 12 | E6: 12 | F6: 0 | G6: 13 | H6: 0 | I6: 0 | J6: 19 | K6: 13 | L6: 22 | M6: 24 | N6: 0 | O6: 23 | P6: 13 | Q6: 20 | R6: 22 | S6: 17 | X6: =SUM(D6:W6) -> 210 | Y6: =COUNT(D6:W6) -> 16 | Z6: =COUNTIF(D6:W6,0) -> 4 | AA6: =Y6-Z6 -> 12 | AB6: =X6/AA6 -> 17.5
C7: Game 5 | D7: 16 | E7: 21 | F7: 0 | G7: 22 | H7: 23 | I7: 21 | J7: 19 | K7: 7 | L7: 12 | M7: 18 | N7: 0 | O7: 20 | P7: 15 | Q7: 0 | R7: 11 | X7: =SUM(D7:W7) -> 205 | Y7: =COUNT(D7:W7) -> 15 | Z7: =COUNTIF(D7:W7,0) -> 3 | AA7: =Y7-Z7 -> 12 | AB7: =X7/AA7 -> 17.083333
C8: Game 6 | D8: 20 | E8: 17 | F8: 18 | G8: 16 | H8: 25 | I8: 10 | J8: 23 | K8: 15 | L8: 0 | M8: 15 | N8: 25 | O8: 18 | X8: =SUM(D8:W8) -> 202 | Y8: =COUNT(D8:W8) -> 12 | Z8: =COUNTIF(D8:W8,0) -> 1 | AA8: =Y8-Z8 -> 11 | AB8: =X8/AA8 -> 18.363636
C9: Game 7 | D9: 24 | E9: 18 | F9: 24 | G9: 21 | H9: 23 | I9: 12 | J9: 14 | K9: 22 | L9: 24 | M9: 21 | X9: =SUM(D9:W9) -> 203 | Y9: =COUNT(D9:W9) -> 10 | Z9: =COUNTIF(D9:W9,0) -> 0 | AA9: =Y9-Z9 -> 10 | AB9: =X9/AA9 -> 20.3
C10: Game 8 | D10: 21 | E10: 22 | F10: 16 | G10: 16 | H10: 13 | I10: 22 | J10: 26 | K10: 12 | L10: 23 | M10: 23 | N10: 7 | X10: =SUM(D10:W10) -> 201 | Y10: =COUNT(D10:W10) -> 11 | Z10: =COUNTIF(D10:W10,0) -> 0 | AA10: =Y10-Z10 -> 11 | AB10: =X10/AA10 -> 18.272727
C11: Game 9 | D11: 24 | E11: 0 | F11: 21 | G11: 18 | H11: 19 | I11: 19 | J11: 7 | K11: 12 | L11: 0 | M11: 0 | N11: 21 | O11: 13 | P11: 23 | Q11: 21 | R11: 11 | X11: =SUM(D11:W11) -> 209 | Y11: =COUNT(D11:W11) -> 15 | Z11: =COUNTIF(D11:W11,0) -> 3 | AA11: =Y11-Z11 -> 12 | AB11: =X11/AA11 -> 17.416667
C12: Game 10 | D12: 18 | E12: 17 | F12: 19 | G12: 0 | H12: 0 | I12: 20 | J12: 13 | K12: 22 | L12: 22 | M12: 15 | N12: 17 | O12: 0 | P12: 17 | Q12: 17 | R12: 23 | X12: =SUM(D12:W12) -> 220 | Y12: =COUNT(D12:W12) -> 15 | Z12: =COUNTIF(D12:W12,0) -> 3 | AA12: =Y12-Z12 -> 12 | AB12: =X12/AA12 -> 18.333333
X13: Averages: | Y13: =AVERAGE(Y3:Y12) -> 13.1 | Z13: =AVERAGE(Z3:Z12) -> 1.6 | AA13: =AVERAGE(AA3:AA12) -> 11.5 | AB13: =AVERAGE(AB3:AB12) -> 18.125671

Sheet 3 Card Bank
B2: Always Bank 3 Cards | D2: Round 1 | E2: Round 2 | F2: Round 3 | G2: Round 4 | H2: Round 5 | I2: Round 6 | J2: Round 7 | K2: Round 8 | L2: Round 9 | M2: Round 10 | N2: Round 11 | O2: Round 12 | P2: Round 13 | Q2: Round 14 | R2: Round 15 | S2: Total | T2: Total Rounds | U2: Total Busts | V2: Successes | W2: Average Score
C3: Game 1 | D3: 30 | E3: 28 | F3: 15 | G3: 0 | H3: 30 | I3: 30 | J3: 31 | K3: 24 | L3: 28 | S3: =SUM(D3:R3) -> 216 | T3: =COUNT(D3:R3) -> 9 | U3: =COUNTIF(D3:R3,0) -> 1 | V3: =T3-U3 -> 8 | W3: =S3/V3 -> 27
C4: Game 2 | D4: 28 | E4: 30 | F4: 32 | G4: 33 | H4: 0 | I4: 0 | J4: 24 | K4: 0 | L4: 26 | M4: 23 | N4: 30 | S4: =SUM(D4:R4) -> 226 | T4: =COUNT(D4:R4) -> 11 | U4: =COUNTIF(D4:R4,0) -> 3 | V4: =T4-U4 -> 8 | W4: =S4/V4 -> 28.25
C5: Game 3 | D5: 0 | E5: 32 | F5: 0 | G5: 0 | H5: 30 | I5: 26 | J5: 24 | K5: 23 | L5: 14 | M5: 0 | N5: 0 | O5: 30 | P5: 22 | S5: =SUM(D5:R5) -> 201 | T5: =COUNT(D5:R5) -> 13 | U5: =COUNTIF(D5:R5,0) -> 5 | V5: =T5-U5 -> 8 | W5: =S5/V5 -> 25.125
C6: Game 4 | D6: 18 | E6: 29 | F6: 29 | G6: 18 | H6: 25 | I6: 0 | J6: 0 | K6: 20 | L6: 0 | M6: 35 | N6: 20 | O6: 25 | S6: =SUM(D6:R6) -> 219 | T6: =COUNT(D6:R6) -> 12 | U6: =COUNTIF(D6:R6,0) -> 3 | V6: =T6-U6 -> 9 | W6: =S6/V6 -> 24.333333
C7: Game 5 | D7: 23 | E7: 25 | F7: 15 | G7: 33 | H7: 33 | I7: 28 | J7: 20 | K7: 0 | L7: 15 | M7: 25 | S7: =SUM(D7:R7) -> 217 | T7: =COUNT(D7:R7) -> 10 | U7: =COUNTIF(D7:R7,0) -> 1 | V7: =T7-U7 -> 9 | W7: =S7/V7 -> 24.111111
C8: Game 6 | D8: 10 | E8: 26 | F8: 31 | G8: 37 | H8: 0 | I8: 19 | J8: 0 | K8: 24 | L8: 26 | M8: 24 | N8: 25 | S8: =SUM(D8:R8) -> 222 | T8: =COUNT(D8:R8) -> 11 | U8: =COUNTIF(D8:R8,0) -> 2 | V8: =T8-U8 -> 9 | W8: =S8/V8 -> 24.666667
C9: Game 7 | D9: 23 | E9: 25 | F9: 0 | G9: 27 | H9: 25 | I9: 0 | J9: 31 | K9: 0 | L9: 33 | M9: 26 | N9: 0 | O9: 0 | P9: 26 | S9: =SUM(D9:R9) -> 216 | T9: =COUNT(D9:R9) -> 13 | U9: =COUNTIF(D9:R9,0) -> 5 | V9: =T9-U9 -> 8 | W9: =S9/V9 -> 27
C10: Game 8 | D10: 0 | E10: 28 | F10: 0 | G10: 32 | H10: 31 | I10: 30 | J10: 25 | K10: 0 | L10: 25 | M10: 0 | N10: 35 | S10: =SUM(D10:R10) -> 206 | T10: =COUNT(D10:R10) -> 11 | U10: =COUNTIF(D10:R10,0) -> 4 | V10: =T10-U10 -> 7 | W10: =S10/V10 -> 29.428571
C11: Game 9 | D11: 27 | E11: 33 | F11: 21 | G11: 27 | H11: 0 | I11: 0 | J11: 31 | K11: 32 | L11: 30 | S11: =SUM(D11:R11) -> 201 | T11: =COUNT(D11:R11) -> 9 | U11: =COUNTIF(D11:R11,0) -> 2 | V11: =T11-U11 -> 7 | W11: =S11/V11 -> 28.714286
C12: Game 10 | D12: 26 | E12: 28 | F12: 24 | G12: 0 | H12: 32 | I12: 35 | J12: 18 | K12: 22 | L12: 7 | M12: 24 | S12: =SUM(D12:R12) -> 216 | T12: =COUNT(D12:R12) -> 10 | U12: =COUNTIF(D12:R12,0) -> 1 | V12: =T12-U12 -> 9 | W12: =S12/V12 -> 24
S13: Averages: | T13: =AVERAGE(T3:T12) -> 10.9 | U13: =AVERAGE(U3:U12) -> 2.7 | V13: =AVERAGE(V3:V12) -> 8.2 | W13: =AVERAGE(W3:W12) -> 26.262897

Sheet 4 Card Bank
B2: Always Bank 4 Cards | D2: Round 1 | E2: Round 2 | F2: Round 3 | G2: Round 4 | H2: Round 5 | I2: Round 6 | J2: Round 7 | K2: Round 8 | L2: Round 9 | M2: Round 10 | N2: Round 11 | O2: Round 12 | P2: Round 13 | Q2: Round 14 | R2: Round 15 | S2: Round 16 | T2: Round 17 | U2: Round 18 | V2: Round 19 | W2: Round 20 | X2: Total | Y2: Total Rounds | Z2: Total Busts | AA2: Successes | AB2: Average Score
C3: Game 1 | D3: 46 | E3: 29 | F3: 0 | G3: 26 | H3: 35 | I3: 40 | J3: 0 | K3: 0 | L3: 0 | M3: 39 | X3: =SUM(D3:W3) -> 215 | Y3: =COUNT(D3:W3) -> 10 | Z3: =COUNTIF(D3:W3,0) -> 4 | AA3: =Y3-Z3 -> 6 | AB3: =X3/AA3 -> 35.833333
C4: Game 2 | D4: 0 | E4: 0 | F4: 32 | G4: 28 | H4: 0 | I4: 0 | J4: 0 | K4: 0 | L4: 0 | M4: 27 | N4: 39 | O4: 45 | P4: 0 | Q4: 46 | X4: =SUM(D4:W4) -> 217 | Y4: =COUNT(D4:W4) -> 14 | Z4: =COUNTIF(D4:W4,0) -> 8 | AA4: =Y4-Z4 -> 6 | AB4: =X4/AA4 -> 36.166667
C5: Game 3 | D5: 38 | E5: 20 | F5: 36 | G5: 32 | H5: 0 | I5: 43 | J5: 36 | X5: =SUM(D5:W5) -> 205 | Y5: =COUNT(D5:W5) -> 7 | Z5: =COUNTIF(D5:W5,0) -> 1 | AA5: =Y5-Z5 -> 6 | AB5: =X5/AA5 -> 34.166667
C6: Game 4 | D6: 7 | E6: 30 | F6: 40 | G6: 0 | H6: 0 | I6: 0 | J6: 33 | K6: 34 | L6: 0 | M6: 36 | N6: 0 | O6: 0 | P6: 37 | X6: =SUM(D6:W6) -> 217 | Y6: =COUNT(D6:W6) -> 13 | Z6: =COUNTIF(D6:W6,0) -> 6 | AA6: =Y6-Z6 -> 7 | AB6: =X6/AA6 -> 31
C7: Game 5 | D7: 32 | E7: 36 | F7: 40 | G7: 0 | H7: 31 | I7: 30 | J7: 0 | K7: 41 | X7: =SUM(D7:W7) -> 210 | Y7: =COUNT(D7:W7) -> 8 | Z7: =COUNTIF(D7:W7,0) -> 2 | AA7: =Y7-Z7 -> 6 | AB7: =X7/AA7 -> 35
C8: Game 6 | D8: 0 | E8: 33 | F8: 0 | G8: 0 | H8: 12 | I8: 30 | J8: 0 | K8: 0 | L8: 0 | M8: 0 | N8: 0 | O8: 0 | P8: 28 | Q8: 0 | R8: 30 | S8: 0 | T8: 31 | U8: 45 | X8: =SUM(D8:W8) -> 209 | Y8: =COUNT(D8:W8) -> 18 | Z8: =COUNTIF(D8:W8,0) -> 11 | AA8: =Y8-Z8 -> 7 | AB8: =X8/AA8 -> 29.857143
C9: Game 7 | D9: 0 | E9: 0 | F9: 0 | G9: 40 | H9: 32 | I9: 0 | J9: 36 | K9: 0 | L9: 7 | M9: 28 | N9: 0 | O9: 0 | P9: 0 | Q9: 36 | R9: 0 | S9: 39 | X9: =SUM(D9:W9) -> 218 | Y9: =COUNT(D9:W9) -> 16 | Z9: =COUNTIF(D9:W9,0) -> 9 | AA9: =Y9-Z9 -> 7 | AB9: =X9/AA9 -> 31.142857
C10: Game 8 | D10: 34 | E10: 0 | F10: 45 | G10: 31 | H10: 24 | I10: 0 | J10: 0 | K10: 42 | L10: 0 | M10: 39 | X10: =SUM(D10:W10) -> 215 | Y10: =COUNT(D10:W10) -> 10 | Z10: =COUNTIF(D10:W10,0) -> 4 | AA10: =Y10-Z10 -> 6 | AB10: =X10/AA10 -> 35.833333
C11: Game 9 | D11: 30 | E11: 0 | F11: 37 | G11: 0 | H11: 0 | I11: 31 | J11: 0 | K11: 0 | L11: 44 | M11: 37 | N11: 34 | X11: =SUM(D11:W11) -> 213 | Y11: =COUNT(D11:W11) -> 11 | Z11: =COUNTIF(D11:W11,0) -> 5 | AA11: =Y11-Z11 -> 6 | AB11: =X11/AA11 -> 35.5
C12: Game 10 | D12: 30 | E12: 36 | F12: 0 | G12: 29 | H12: 0 | I12: 36 | J12: 0 | K12: 32 | L12: 41 | X12: =SUM(D12:W12) -> 204 | Y12: =COUNT(D12:W12) -> 9 | Z12: =COUNTIF(D12:W12,0) -> 3 | AA12: =Y12-Z12 -> 6 | AB12: =X12/AA12 -> 34
X13: Averages: | Y13: =AVERAGE(Y3:Y12) -> 11.6 | Z13: =AVERAGE(Z3:Z12) -> 5.3 | AA13: =AVERAGE(AA3:AA12) -> 6.3 | AB13: =AVERAGE(AB3:AB12) -> 33.85

Sheet Flip7 or Bust
B2: Always Flip 7 | D2: Round 1 | E2: Round 2 | F2: Round 3 | G2: Round 4 | H2: Round 5 | I2: Round 6 | J2: Round 7 | K2: Round 8 | L2: Round 9 | M2: Round 10 | N2: Round 11 | O2: Round 12 | P2: Round 13 | Q2: Round 14 | R2: Round 15 | S2: Total | T2: Total Rounds | U2: Total Busts | V2: Successes | W2: Average Score
C3: Game 1 | S3: =SUM(D3:R3) -> 0 | T3: =COUNT(D3:R3) -> 0 | U3: =COUNTIF(D3:R3,0) -> 0 | V3: =T3-U3 -> 0 | W3: =S3/V3 -> #DIV/0!
C4: Game 2 | S4: =SUM(D4:R4) -> 0 | T4: =COUNT(D4:R4) -> 0 | U4: =COUNTIF(D4:R4,0) -> 0 | V4: =T4-U4 -> 0 | W4: =S4/V4 -> #DIV/0!
C5: Game 3 | S5: =SUM(D5:R5) -> 0 | T5: =COUNT(D5:R5) -> 0 | U5: =COUNTIF(D5:R5,0) -> 0 | V5: =T5-U5 -> 0 | W5: =S5/V5 -> #DIV/0!
C6: Game 4 | S6: =SUM(D6:R6) -> 0 | T6: =COUNT(D6:R6) -> 0 | U6: =COUNTIF(D6:R6,0) -> 0 | V6: =T6-U6 -> 0 | W6: =S6/V6 -> #DIV/0!
C7: Game 5 | S7: =SUM(D7:R7) -> 0 | T7: =COUNT(D7:R7) -> 0 | U7: =COUNTIF(D7:R7,0) -> 0 | V7: =T7-U7 -> 0 | W7: =S7/V7 -> #DIV/0!
C8: Game 6 | S8: =SUM(D8:R8) -> 0 | T8: =COUNT(D8:R8) -> 0 | U8: =COUNTIF(D8:R8,0) -> 0 | V8: =T8-U8 -> 0 | W8: =S8/V8 -> #DIV/0!
C9: Game 7 | S9: =SUM(D9:R9) -> 0 | T9: =COUNT(D9:R9) -> 0 | U9: =COUNTIF(D9:R9,0) -> 0 | V9: =T9-U9 -> 0 | W9: =S9/V9 -> #DIV/0!
C10: Game 8 | S10: =SUM(D10:R10) -> 0 | T10: =COUNT(D10:R10) -> 0 | U10: =COUNTIF(D10:R10,0) -> 0 | V10: =T10-U10 -> 0 | W10: =S10/V10 -> #DIV/0!
C11: Game 9 | S11: =SUM(D11:R11) -> 0 | T11: =COUNT(D11:R11) -> 0 | U11: =COUNTIF(D11:R11,0) -> 0 | V11: =T11-U11 -> 0 | W11: =S11/V11 -> #DIV/0!
C12: Game 10 | S12: =SUM(D12:R12) -> 0 | T12: =COUNT(D12:R12) -> 0 | U12: =COUNTIF(D12:R12,0) -> 0 | V12: =T12-U12 -> 0 | W12: =S12/V12 -> #DIV/0!
S13: Averages: | T13: =AVERAGE(T3:T12) -> 0 | U13: =AVERAGE(U3:U12) -> 0 | V13: =AVERAGE(V3:V12) -> 0 | W13: =AVERAGE(W3:W12) -> #DIV/0!

Sheet Score 20 Bank
B2: Always Bank 20+ Points | D2: Round 1 | E2: Round 2 | F2: Round 3 | G2: Round 4 | H2: Round 5 | I2: Round 6 | J2: Round 7 | K2: Round 8 | L2: Round 9 | M2: Round 10 | N2: Round 11 | O2: Round 12 | P2: Round 13 | Q2: Round 14 | R2: Round 15 | S2: Total | T2: Total Rounds | U2: Total Busts | V2: Successes | W2: Average Score
C3: Game 1 | D3: 20 | E3: 0 | F3: 23 | G3: 0 | H3: 25 | I3: 24 | J3: 27 | K3: 25 | L3: 26 | M3: 21 | N3: 20 | S3: =SUM(D3:R3) -> 211 | T3: =COUNT(D3:R3) -> 11 | U3: =COUNTIF(D3:R3,0) -> 2 | V3: =T3-U3 -> 9 | W3: =S3/V3 -> 23.444444
C4: Game 2 | D4: 0 | E4: 22 | F4: 27 | G4: 20 | H4: 0 | I4: 30 | J4: 21 | K4: 0 | L4: 24 | M4: 20 | N4: 32 | O4: 24 | S4: =SUM(D4:R4) -> 220 | T4: =COUNT(D4:R4) -> 12 | U4: =COUNTIF(D4:R4,0) -> 3 | V4: =T4-U4 -> 9 | W4: =S4/V4 -> 24.444444
C5: Game 3 | D5: 0 | E5: 22 | F5: 28 | G5: 24 | H5: 23 | I5: 24 | J5: 23 | K5: 0 | L5: 22 | M5: 31 | N5: 23 | S5: =SUM(D5:R5) -> 220 | T5: =COUNT(D5:R5) -> 11 | U5: =COUNTIF(D5:R5,0) -> 2 | V5: =T5-U5 -> 9 | W5: =S5/V5 -> 24.444444
C6: Game 4 | D6: 27 | E6: 22 | F6: 25 | G6: 23 | H6: 23 | I6: 24 | J6: 27 | K6: 21 | L6: 20 | S6: =SUM(D6:R6) -> 212 | T6: =COUNT(D6:R6) -> 9 | U6: =COUNTIF(D6:R6,0) -> 0 | V6: =T6-U6 -> 9 | W6: =S6/V6 -> 23.555556
C7: Game 5 | D7: 24 | E7: 0 | F7: 21 | G7: 22 | H7: 21 | I7: 0 | J7: 0 | K7: 28 | L7: 24 | M7: 27 | N7: 25 | O7: 28 | S7: =SUM(D7:R7) -> 220 | T7: =COUNT(D7:R7) -> 12 | U7: =COUNTIF(D7:R7,0) -> 3 | V7: =T7-U7 -> 9 | W7: =S7/V7 -> 24.444444
C8: Game 6 | D8: 27 | E8: 25 | F8: 25 | G8: 28 | H8: 25 | I8: 22 | J8: 26 | K8: 0 | L8: 25 | S8: =SUM(D8:R8) -> 203 | T8: =COUNT(D8:R8) -> 9 | U8: =COUNTIF(D8:R8,0) -> 1 | V8: =T8-U8 -> 8 | W8: =S8/V8 -> 25.375
C9: Game 7 | D9: 30 | E9: 23 | F9: 20 | G9: 0 | H9: 25 | I9: 21 | J9: 21 | K9: 22 | L9: 21 | M9: 0 | N9: 25 | S9: =SUM(D9:R9) -> 208 | T9: =COUNT(D9:R9) -> 11 | U9: =COUNTIF(D9:R9,0) -> 2 | V9: =T9-U9 -> 9 | W9: =S9/V9 -> 23.111111
C10: Game 8 | D10: 22 | E10: 20 | F10: 27 | G10: 0 | H10: 26 | I10: 32 | J10: 20 | K10: 21 | L10: 0 | M10: 23 | N10: 21 | S10: =SUM(D10:R10) -> 212 | T10: =COUNT(D10:R10) -> 11 | U10: =COUNTIF(D10:R10,0) -> 2 | V10: =T10-U10 -> 9 | W10: =S10/V10 -> 23.555556
C11: Game 9 | D11: 24 | E11: 28 | F11: 23 | G11: 22 | H11: 0 | I11: 22 | J11: 0 | K11: 28 | L11: 24 | M11: 22 | N11: 22 | S11: =SUM(D11:R11) -> 215 | T11: =COUNT(D11:R11) -> 11 | U11: =COUNTIF(D11:R11,0) -> 2 | V11: =T11-U11 -> 9 | W11: =S11/V11 -> 23.888889
C12: Game 10 | D12: 27 | E12: 21 | F12: 27 | G12: 23 | H12: 26 | I12: 22 | J12: 28 | K12: 20 | L12: 23 | S12: =SUM(D12:R12) -> 217 | T12: =COUNT(D12:R12) -> 9 | U12: =COUNTIF(D12:R12,0) -> 0 | V12: =T12-U12 -> 9 | W12: =S12/V12 -> 24.111111
S13: Averages: | T13: =AVERAGE(T3:T12) -> 10.6 | U13: =AVERAGE(U3:U12) -> 1.7 | V13: =AVERAGE(V3:V12) -> 8.9 | W13: =AVERAGE(W3:W12) -> 24.0375

Sheet Score 25 Bank
B2: Always Bank 25+ Points | D2: Round 1 | E2: Round 2 | F2: Round 3 | G2: Round 4 | H2: Round 5 | I2: Round 6 | J2: Round 7 | K2: Round 8 | L2: Round 9 | M2: Round 10 | N2: Round 11 | O2: Round 12 | P2: Round 13 | Q2: Round 14 | R2: Round 15 | S2: Total | T2: Total Rounds | U2: Total Busts | V2: Successes | W2: Average Score
C3: Game 1 | D3: 0 | E3: 0 | F3: 26 | G3: 0 | H3: 30 | I3: 29 | J3: 34 | K3: 29 | L3: 25 | M3: 34 | S3: =SUM(D3:R3) -> 207 | T3: =COUNT(D3:R3) -> 10 | U3: =COUNTIF(D3:R3,0) -> 3 | V3: =T3-U3 -> 7 | W3: =S3/V3 -> 29.571429
C4: Game 2 | D4: 28 | E4: 33 | F4: 31 | G4: 32 | H4: 30 | I4: 32 | J4: 0 | K4: 30 | S4: =SUM(D4:R4) -> 216 | T4: =COUNT(D4:R4) -> 8 | U4: =COUNTIF(D4:R4,0) -> 1 | V4: =T4-U4 -> 7 | W4: =S4/V4 -> 30.857143
C5: Game 3 | D5: 31 | E5: 27 | F5: 33 | G5: 0 | H5: 0 | I5: 31 | J5: 0 | K5: 29 | L5: 32 | M5: 0 | N5: 25 | S5: =SUM(D5:R5) -> 208 | T5: =COUNT(D5:R5) -> 11 | U5: =COUNTIF(D5:R5,0) -> 4 | V5: =T5-U5 -> 7 | W5: =S5/V5 -> 29.714286
C6: Game 4 | D6: 0 | E6: 28 | F6: 0 | G6: 34 | H6: 35 | I6: 0 | J6: 26 | K6: 0 | L6: 35 | M6: 29 | N6: 0 | O6: 27 | S6: =SUM(D6:R6) -> 214 | T6: =COUNT(D6:R6) -> 12 | U6: =COUNTIF(D6:R6,0) -> 5 | V6: =T6-U6 -> 7 | W6: =S6/V6 -> 30.571429
C7: Game 5 | D7: 28 | E7: 0 | F7: 34 | G7: 0 | H7: 30 | I7: 0 | J7: 0 | K7: 25 | L7: 33 | M7: 26 | N7: 0 | O7: 0 | P7: 27 | S7: =SUM(D7:R7) -> 203 | T7: =COUNT(D7:R7) -> 13 | U7: =COUNTIF(D7:R7,0) -> 6 | V7: =T7-U7 -> 7 | W7: =S7/V7 -> 29
C8: Game 6 | D8: 29 | E8: 29 | F8: 0 | G8: 0 | H8: 0 | I8: 35 | J8: 26 | K8: 0 | L8: 33 | M8: 0 | N8: 0 | O8: 30 | P8: 25 | S8: =SUM(D8:R8) -> 207 | T8: =COUNT(D8:R8) -> 13 | U8: =COUNTIF(D8:R8,0) -> 6 | V8: =T8-U8 -> 7 | W8: =S8/V8 -> 29.571429
C9: Game 7 | D9: 28 | E9: 31 | F9: 28 | G9: 0 | H9: 34 | I9: 31 | J9: 27 | K9: 32 | S9: =SUM(D9:R9) -> 211 | T9: =COUNT(D9:R9) -> 8 | U9: =COUNTIF(D9:R9,0) -> 1 | V9: =T9-U9 -> 7 | W9: =S9/V9 -> 30.142857
C10: Game 8 | D10: 32 | E10: 0 | F10: 25 | G10: 27 | H10: 26 | I10: 0 | J10: 27 | K10: 31 | L10: 25 | M10: 27 | S10: =SUM(D10:R10) -> 220 | T10: =COUNT(D10:R10) -> 10 | U10: =COUNTIF(D10:R10,0) -> 2 | V10: =T10-U10 -> 8 | W10: =S10/V10 -> 27.5
C11: Game 9 | D11: 29 | E11: 30 | F11: 0 | G11: 32 | H11: 29 | I11: 30 | J11: 27 | K11: 27 | S11: =SUM(D11:R11) -> 204 | T11: =COUNT(D11:R11) -> 8 | U11: =COUNTIF(D11:R11,0) -> 1 | V11: =T11-U11 -> 7 | W11: =S11/V11 -> 29.142857
C12: Game 10 | D12: 0 | E12: 0 | F12: 32 | G12: 33 | H12: 0 | I12: 35 | J12: 32 | K12: 29 | L12: 0 | M12: 26 | N12: 0 | O12: 0 | P12: 28 | S12: =SUM(D12:R12) -> 215 | T12: =COUNT(D12:R12) -> 13 | U12: =COUNTIF(D12:R12,0) -> 6 | V12: =T12-U12 -> 7 | W12: =S12/V12 -> 30.714286
S13: Averages: | T13: =AVERAGE(T3:T12) -> 10.6 | U13: =AVERAGE(U3:U12) -> 3.5 | V13: =AVERAGE(V3:V12) -> 7.1 | W13: =AVERAGE(W3:W12) -> 29.678571

Sheet Score 30 Bank
B2: Always Bank 30+ Points | D2: Round 1 | E2: Round 2 | F2: Round 3 | G2: Round 4 | H2: Round 5 | I2: Round 6 | J2: Round 7 | K2: Round 8 | L2: Round 9 | M2: Round 10 | N2: Round 11 | O2: Round 12 | P2: Round 13 | Q2: Round 14 | R2: Round 15 | S2: Total | T2: Total Rounds | U2: Total Busts | V2: Successes | W2: Average Score
C3: Game 1 | D3: 37 | E3: 30 | F3: 0 | G3: 0 | H3: 38 | I3: 34 | J3: 31 | K3: 0 | L3: 34 | S3: =SUM(D3:R3) -> 204 | T3: =COUNT(D3:R3) -> 9 | U3: =COUNTIF(D3:R3,0) -> 3 | V3: =T3-U3 -> 6 | W3: =S3/V3 -> 34
C4: Game 2 | D4: 35 | E4: 0 | F4: 0 | G4: 32 | H4: 0 | I4: 31 | J4: 35 | K4: 31 | L4: 35 | M4: 57 | S4: =SUM(D4:R4) -> 256 | T4: =COUNT(D4:R4) -> 10 | U4: =COUNTIF(D4:R4,0) -> 3 | V4: =T4-U4 -> 7 | W4: =S4/V4 -> 36.571429
C5: Game 3 | D5: 0 | E5: 34 | F5: 38 | G5: 30 | H5: 37 | I5: 37 | J5: 37 | S5: =SUM(D5:R5) -> 213 | T5: =COUNT(D5:R5) -> 7 | U5: =COUNTIF(D5:R5,0) -> 1 | V5: =T5-U5 -> 6 | W5: =S5/V5 -> 35.5
C6: Game 4 | D6: 0 | E6: 32 | F6: 33 | G6: 0 | H6: 42 | I6: 35 | J6: 0 | K6: 34 | L6: 0 | M6: 0 | N6: 38 | S6: =SUM(D6:R6) -> 214 | T6: =COUNT(D6:R6) -> 11 | U6: =COUNTIF(D6:R6,0) -> 5 | V6: =T6-U6 -> 6 | W6: =S6/V6 -> 35.666667
C7: Game 5 | D7: 37 | E7: 0 | F7: 33 | G7: 33 | H7: 0 | I7: 0 | J7: 0 | K7: 33 | L7: 32 | M7: 32 | S7: =SUM(D7:R7) -> 200 | T7: =COUNT(D7:R7) -> 10 | U7: =COUNTIF(D7:R7,0) -> 4 | V7: =T7-U7 -> 6 | W7: =S7/V7 -> 33.333333
C8: Game 6 | D8: 36 | E8: 30 | F8: 36 | G8: 34 | H8: 30 | I8: 30 | J8: 35 | S8: =SUM(D8:R8) -> 231 | T8: =COUNT(D8:R8) -> 7 | U8: =COUNTIF(D8:R8,0) -> 0 | V8: =T8-U8 -> 7 | W8: =S8/V8 -> 33
C9: Game 7 | D9: 0 | E9: 0 | F9: 0 | G9: 33 | H9: 40 | I9: 30 | J9: 30 | K9: 0 | L9: 34 | M9: 32 | N9: 32 | S9: =SUM(D9:R9) -> 231 | T9: =COUNT(D9:R9) -> 11 | U9: =COUNTIF(D9:R9,0) -> 4 | V9: =T9-U9 -> 7 | W9: =S9/V9 -> 33
C10: Game 8 | D10: 0 | E10: 0 | F10: 34 | G10: 31 | H10: 34 | I10: 0 | J10: 36 | K10: 36 | L10: 30 | S10: =SUM(D10:R10) -> 201 | T10: =COUNT(D10:R10) -> 9 | U10: =COUNTIF(D10:R10,0) -> 3 | V10: =T10-U10 -> 6 | W10: =S10/V10 -> 33.5
C11: Game 9 | D11: 35 | E11: 0 | F11: 30 | G11: 36 | H11: 0 | I11: 0 | J11: 36 | K11: 0 | L11: 37 | M11: 30 | S11: =SUM(D11:R11) -> 204 | T11: =COUNT(D11:R11) -> 10 | U11: =COUNTIF(D11:R11,0) -> 4 | V11: =T11-U11 -> 6 | W11: =S11/V11 -> 34
C12: Game 10 | D12: 31 | E12: 0 | F12: 37 | G12: 0 | H12: 30 | I12: 31 | J12: 33 | K12: 36 | L12: 30 | S12: =SUM(D12:R12) -> 228 | T12: =COUNT(D12:R12) -> 9 | U12: =COUNTIF(D12:R12,0) -> 2 | V12: =T12-U12 -> 7 | W12: =S12/V12 -> 32.571429
S13: Averages: | T13: =AVERAGE(T3:T12) -> 9.3 | U13: =AVERAGE(U3:U12) -> 2.9 | V13: =AVERAGE(V3:V12) -> 6.4 | W13: =AVERAGE(W3:W12) -> 34.114286

Sheet Score 35 Bank
B2: Always Bank 35+ Points | D2: Round 1 | E2: Round 2 | F2: Round 3 | G2: Round 4 | H2: Round 5 | I2: Round 6 | J2: Round 7 | K2: Round 8 | L2: Round 9 | M2: Round 10 | N2: Round 11 | O2: Round 12 | P2: Round 13 | Q2: Round 14 | R2: Round 15 | S2: Round 16 | T2: Round 17 | U2: Round 18 | V2: Round 19 | W2: Round 20 | X2: Total | Y2: Total Rounds | Z2: Total Busts | AA2: Successes | AB2: Average Score
C3: Game 1 | D3: 36 | E3: 38 | F3: 0 | G3: 44 | H3: 0 | I3: 42 | J3: 0 | K3: 37 | L3: 37 | X3: =SUM(D3:W3) -> 234 | Y3: =COUNT(D3:W3) -> 9 | Z3: =COUNTIF(D3:W3,0) -> 3 | AA3: =Y3-Z3 -> 6 | AB3: =X3/AA3 -> 39
C4: Game 2 | D4: 0 | E4: 62 | F4: 0 | G4: 0 | H4: 0 | I4: 0 | J4: 37 | K4: 37 | L4: 38 | M4: 0 | N4: 43 | X4: =SUM(D4:W4) -> 217 | Y4: =COUNT(D4:W4) -> 11 | Z4: =COUNTIF(D4:W4,0) -> 6 | AA4: =Y4-Z4 -> 5 | AB4: =X4/AA4 -> 43.4
C5: Game 3 | D5: 38 | E5: 0 | F5: 0 | G5: 0 | H5: 40 | I5: 0 | J5: 0 | K5: 0 | L5: 43 | M5: 42 | N5: 38 | X5: =SUM(D5:W5) -> 201 | Y5: =COUNT(D5:W5) -> 11 | Z5: =COUNTIF(D5:W5,0) -> 6 | AA5: =Y5-Z5 -> 5 | AB5: =X5/AA5 -> 40.2
C6: Game 4 | D6: 0 | E6: 0 | F6: 0 | G6: 0 | H6: 0 | I6: 57 | J6: 0 | K6: 0 | L6: 0 | M6: 40 | N6: 0 | O6: 38 | P6: 0 | Q6: 43 | R6: 42 | X6: =SUM(D6:W6) -> 220 | Y6: =COUNT(D6:W6) -> 15 | Z6: =COUNTIF(D6:W6,0) -> 10 | AA6: =Y6-Z6 -> 5 | AB6: =X6/AA6 -> 44
C7: Game 5 | D7: 0 | E7: 36 | F7: 0 | G7: 0 | H7: 0 | I7: 40 | J7: 0 | K7: 0 | L7: 35 | M7: 39 | N7: 36 | O7: 42 | X7: =SUM(D7:W7) -> 228 | Y7: =COUNT(D7:W7) -> 12 | Z7: =COUNTIF(D7:W7,0) -> 6 | AA7: =Y7-Z7 -> 6 | AB7: =X7/AA7 -> 38
C8: Game 6 | D8: 38 | E8: 43 | F8: 0 | G8: 0 | H8: 39 | I8: 42 | J8: 0 | K8: 0 | L8: 38 | X8: =SUM(D8:W8) -> 200 | Y8: =COUNT(D8:W8) -> 9 | Z8: =COUNTIF(D8:W8,0) -> 4 | AA8: =Y8-Z8 -> 5 | AB8: =X8/AA8 -> 40
C9: Game 7 | D9: 0 | E9: 0 | F9: 39 | G9: 0 | H9: 44 | I9: 0 | J9: 0 | K9: 0 | L9: 0 | M9: 0 | N9: 36 | O9: 0 | P9: 0 | Q9: 0 | R9: 0 | S9: 0 | T9: 0 | U9: 45 | V9: 39 | X9: =SUM(D9:W9) -> 203 | Y9: =COUNT(D9:W9) -> 19 | Z9: =COUNTIF(D9:W9,0) -> 14 | AA9: =Y9-Z9 -> 5 | AB9: =X9/AA9 -> 40.6
C10: Game 8 | D10: 36 | E10: 44 | F10: 0 | G10: 42 | H10: 35 | I10: 45 | X10: =SUM(D10:W10) -> 202 | Y10: =COUNT(D10:W10) -> 6 | Z10: =COUNTIF(D10:W10,0) -> 1 | AA10: =Y10-Z10 -> 5 | AB10: =X10/AA10 -> 40.4
C11: Game 9 | D11: 45 | E11: 0 | F11: 0 | G11: 36 | H11: 0 | I11: 37 | J11: 0 | K11: 0 | L11: 35 | M11: 36 | N11: 0 | O11: 41 | X11: =SUM(D11:W11) -> 230 | Y11: =COUNT(D11:W11) -> 12 | Z11: =COUNTIF(D11:W11,0) -> 6 | AA11: =Y11-Z11 -> 6 | AB11: =X11/AA11 -> 38.333333
C12: Game 10 | D12: 0 | E12: 0 | F12: 45 | G12: 0 | H12: 0 | I12: 0 | J12: 38 | K12: 35 | L12: 0 | M12: 0 | N12: 37 | O12: 43 | P12: 38 | X12: =SUM(D12:W12) -> 236 | Y12: =COUNT(D12:W12) -> 13 | Z12: =COUNTIF(D12:W12,0) -> 7 | AA12: =Y12-Z12 -> 6 | AB12: =X12/AA12 -> 39.333333
X13: Averages: | Y13: =AVERAGE(Y3:Y12) -> 11.7 | Z13: =AVERAGE(Z3:Z12) -> 6.3 | AA13: =AVERAGE(AA3:AA12) -> 5.4 | AB13: =AVERAGE(AB3:AB12) -> 40.326667

Sheet Score 40 Bank
B2: Always Bank 40+ Points | D2: Round 1 | E2: Round 2 | F2: Round 3 | G2: Round 4 | H2: Round 5 | I2: Round 6 | J2: Round 7 | K2: Round 8 | L2: Round 9 | M2: Round 10 | N2: Round 11 | O2: Round 12 | P2: Round 13 | Q2: Round 14 | R2: Round 15 | S2: Round 16 | T2: Round 17 | U2: Round 18 | V2: Round 19 | W2: Round 20 | X2: Round 21 | Y2: Round 22 | Z2: Round 23 | AA2: Round 24 | AB2: Round 25 | AC2: Round 26 | AD2: Round 27 | AE2: Round 28 | AF2: Round 29 | AG2: Round 30 | AH2: Total | AI2: Total Rounds | AJ2: Total Busts | AK2: Successes | AL2: Average Score
C3: Game 1 | D3: 0 | E3: 0 | F3: 0 | G3: 0 | H3: 40 | I3: 0 | J3: 0 | K3: 0 | L3: 47 | M3: 0 | N3: 0 | O3: 0 | P3: 0 | Q3: 40 | R3: 45 | S3: 0 | T3: 43 | AH3: =SUM(D3:AG3) -> 215 | AI3: =COUNT(D3:AG3) -> 17 | AJ3: =COUNTIF(D3:AG3,0) -> 12 | AK3: =AI3-AJ3 -> 5 | AL3: =AH3/AK3 -> 43
C4: Game 2 | D4: 0 | E4: 0 | F4: 42 | G4: 0 | H4: 0 | I4: 40 | J4: 52 | K4: 0 | L4: 40 | M4: 44 | AH4: =SUM(D4:AG4) -> 218 | AI4: =COUNT(D4:AG4) -> 10 | AJ4: =COUNTIF(D4:AG4,0) -> 5 | AK4: =AI4-AJ4 -> 5 | AL4: =AH4/AK4 -> 43.6
C5: Game 3 | D5: 0 | E5: 0 | F5: 49 | G5: 43 | H5: 41 | I5: 0 | J5: 0 | K5: 0 | L5: 0 | M5: 0 | N5: 47 | O5: 0 | P5: 0 | Q5: 42 | AH5: =SUM(D5:AG5) -> 222 | AI5: =COUNT(D5:AG5) -> 14 | AJ5: =COUNTIF(D5:AG5,0) -> 9 | AK5: =AI5-AJ5 -> 5 | AL5: =AH5/AK5 -> 44.4
C6: Game 4 | D6: 45 | E6: 0 | F6: 46 | G6: 49 | H6: 0 | I6: 0 | J6: 43 | K6: 0 | L6: 0 | M6: 43 | AH6: =SUM(D6:AG6) -> 226 | AI6: =COUNT(D6:AG6) -> 10 | AJ6: =COUNTIF(D6:AG6,0) -> 5 | AK6: =AI6-AJ6 -> 5 | AL6: =AH6/AK6 -> 45.2
C7: Game 5 | D7: 0 | E7: 40 | F7: 41 | G7: 0 | H7: 0 | I7: 0 | J7: 0 | K7: 45 | L7: 0 | M7: 0 | N7: 46 | O7: 40 | AH7: =SUM(D7:AG7) -> 212 | AI7: =COUNT(D7:AG7) -> 12 | AJ7: =COUNTIF(D7:AG7,0) -> 7 | AK7: =AI7-AJ7 -> 5 | AL7: =AH7/AK7 -> 42.4
C8: Game 6 | D8: 0 | E8: 46 | F8: 44 | G8: 47 | H8: 47 | I8: 0 | J8: 48 | AH8: =SUM(D8:AG8) -> 232 | AI8: =COUNT(D8:AG8) -> 7 | AJ8: =COUNTIF(D8:AG8,0) -> 2 | AK8: =AI8-AJ8 -> 5 | AL8: =AH8/AK8 -> 46.4
C9: Game 7 | D9: 0 | E9: 45 | F9: 47 | G9: 49 | H9: 0 | I9: 0 | J9: 46 | K9: 46 | AH9: =SUM(D9:AG9) -> 233 | AI9: =COUNT(D9:AG9) -> 8 | AJ9: =COUNTIF(D9:AG9,0) -> 3 | AK9: =AI9-AJ9 -> 5 | AL9: =AH9/AK9 -> 46.6
C10: Game 8 | D10: 0 | E10: 0 | F10: 40 | G10: 43 | H10: 48 | I10: 46 | J10: 40 | AH10: =SUM(D10:AG10) -> 217 | AI10: =COUNT(D10:AG10) -> 7 | AJ10: =COUNTIF(D10:AG10,0) -> 2 | AK10: =AI10-AJ10 -> 5 | AL10: =AH10/AK10 -> 43.4
C11: Game 9 | D11: 0 | E11: 0 | F11: 0 | G11: 40 | H11: 0 | I11: 0 | J11: 0 | K11: 42 | L11: 0 | M11: 0 | N11: 0 | O11: 0 | P11: 43 | Q11: 0 | R11: 0 | S11: 0 | T11: 0 | U11: 0 | V11: 0 | W11: 0 | X11: 0 | Y11: 47 | Z11: 0 | AA11: 0 | AB11: 0 | AC11: 43 | AH11: =SUM(D11:AG11) -> 215 | AI11: =COUNT(D11:AG11) -> 26 | AJ11: =COUNTIF(D11:AG11,0) -> 21 | AK11: =AI11-AJ11 -> 5 | AL11: =AH11/AK11 -> 43
C12: Game 10 | D12: 0 | E12: 0 | F12: 43 | G12: 43 | H12: 0 | I12: 0 | J12: 0 | K12: 0 | L12: 47 | M12: 0 | N12: 0 | O12: 44 | P12: 51 | AH12: =SUM(D12:AG12) -> 228 | AI12: =COUNT(D12:AG12) -> 13 | AJ12: =COUNTIF(D12:AG12,0) -> 8 | AK12: =AI12-AJ12 -> 5 | AL12: =AH12/AK12 -> 45.6
AH13: Averages: | AI13: =AVERAGE(AI3:AI12) -> 12.4 | AJ13: =AVERAGE(AJ3:AJ12) -> 7.4 | AK13: =AVERAGE(AK3:AK12) -> 5 | AL13: =AVERAGE(AL3:AL12) -> 44.36

Sheet Cumulative Odds 70%
B2: Flip until Cumu Odds < 70% | D2: Round 1 | E2: Round 2 | F2: Round 3 | G2: Round 4 | H2: Round 5 | I2: Round 6 | J2: Round 7 | K2: Round 8 | L2: Round 9 | M2: Round 10 | N2: Round 11 | O2: Round 12 | P2: Round 13 | Q2: Round 14 | R2: Round 15 | S2: Round 16 | T2: Round 17 | U2: Round 18 | V2: Round 19 | W2: Round 20 | X2: Total | Y2: Total Rounds | Z2: Total Busts | AA2: Successes | AB2: Average Score
B3: Also wont bank 0 | C3: Game 1 | D3: 24 | E3: 0 | F3: 0 | G3: 26 | H3: 31 | I3: 28 | J3: 17 | K3: 0 | L3: 0 | M3: 28 | N3: 0 | O3: 25 | P3: 0 | Q3: 22 | X3: =SUM(D3:R3) -> 201 | Y3: =COUNT(D3:R3) -> 14 | Z3: =COUNTIF(D3:R3,0) -> 6 | AA3: =Y3-Z3 -> 8 | AB3: =X3/AA3 -> 25.125
C4: Game 2 | D4: 0 | E4: 25 | F4: 0 | G4: 31 | H4: 22 | I4: 30 | J4: 22 | K4: 22 | L4: 30 | M4: 21 | X4: =SUM(D4:R4) -> 203 | Y4: =COUNT(D4:R4) -> 10 | Z4: =COUNTIF(D4:R4,0) -> 2 | AA4: =Y4-Z4 -> 8 | AB4: =X4/AA4 -> 25.375
C5: Game 3 | D5: 0 | E5: 35 | F5: 0 | G5: 0 | H5: 25 | I5: 0 | J5: 0 | K5: 25 | L5: 0 | M5: 33 | N5: 34 | O5: 21 | P5: 26 | Q5: 19 | X5: =SUM(D5:R5) -> 218 | Y5: =COUNT(D5:R5) -> 14 | Z5: =COUNTIF(D5:R5,0) -> 6 | AA5: =Y5-Z5 -> 8 | AB5: =X5/AA5 -> 27.25
C6: Game 4 | D6: 31 | E6: 23 | F6: 22 | G6: 21 | H6: 26 | I6: 30 | J6: 23 | K6: 36 | X6: =SUM(D6:R6) -> 212 | Y6: =COUNT(D6:R6) -> 8 | Z6: =COUNTIF(D6:R6,0) -> 0 | AA6: =Y6-Z6 -> 8 | AB6: =X6/AA6 -> 26.5
C7: Game 5 | D7: 34 | E7: 26 | F7: 26 | G7: 29 | H7: 23 | I7: 26 | J7: 27 | K7: 21 | X7: =SUM(D7:R7) -> 212 | Y7: =COUNT(D7:R7) -> 8 | Z7: =COUNTIF(D7:R7,0) -> 0 | AA7: =Y7-Z7 -> 8 | AB7: =X7/AA7 -> 26.5
C8: Game 6 | D8: 0 | E8: 27 | F8: 25 | G8: 26 | H8: 19 | I8: 20 | J8: 0 | K8: 32 | L8: 27 | M8: 28 | X8: =SUM(D8:R8) -> 204 | Y8: =COUNT(D8:R8) -> 10 | Z8: =COUNTIF(D8:R8,0) -> 2 | AA8: =Y8-Z8 -> 8 | AB8: =X8/AA8 -> 25.5
C9: Game 7 | D9: 30 | E9: 25 | F9: 28 | G9: 29 | H9: 18 | I9: 24 | J9: 0 | K9: 24 | L9: 0 | M9: 21 | N9: 26 | X9: =SUM(D9:R9) -> 225 | Y9: =COUNT(D9:R9) -> 11 | Z9: =COUNTIF(D9:R9,0) -> 2 | AA9: =Y9-Z9 -> 9 | AB9: =X9/AA9 -> 25
C10: Game 8 | D10: 0 | E10: 24 | F10: 0 | G10: 20 | H10: 26 | I10: 20 | J10: 0 | K10: 24 | L10: 20 | M10: 25 | N10: 0 | O10: 25 | P10: 22 | X10: =SUM(D10:R10) -> 206 | Y10: =COUNT(D10:R10) -> 13 | Z10: =COUNTIF(D10:R10,0) -> 4 | AA10: =Y10-Z10 -> 9 | AB10: =X10/AA10 -> 22.888889
C11: Game 9 | D11: 30 | E11: 25 | F11: 19 | G11: 0 | H11: 22 | I11: 0 | J11: 18 | K11: 24 | L11: 28 | M11: 26 | N11: 22 | X11: =SUM(D11:R11) -> 214 | Y11: =COUNT(D11:R11) -> 11 | Z11: =COUNTIF(D11:R11,0) -> 2 | AA11: =Y11-Z11 -> 9 | AB11: =X11/AA11 -> 23.777778
C12: Game 10 | D12: 29 | E12: 0 | F12: 22 | G12: 0 | H12: 24 | I12: 0 | J12: 20 | K12: 24 | L12: 33 | M12: 26 | N12: 23 | X12: =SUM(D12:R12) -> 201 | Y12: =COUNT(D12:R12) -> 11 | Z12: =COUNTIF(D12:R12,0) -> 3 | AA12: =Y12-Z12 -> 8 | AB12: =X12/AA12 -> 25.125
X13: Averages: | Y13: =AVERAGE(Y3:Y12) -> 11 | Z13: =AVERAGE(Z3:Z12) -> 2.7 | AA13: =AVERAGE(AA3:AA12) -> 8.3 | AB13: =AVERAGE(AB3:AB12) -> 25.304167

Sheet Cumulative Odds 60%
B2: Flip until Cumu Odds < 60% | D2: Round 1 | E2: Round 2 | F2: Round 3 | G2: Round 4 | H2: Round 5 | I2: Round 6 | J2: Round 7 | K2: Round 8 | L2: Round 9 | M2: Round 10 | N2: Round 11 | O2: Round 12 | P2: Round 13 | Q2: Round 14 | R2: Round 15 | S2: Total | T2: Total Rounds | U2: Total Busts | V2: Successes | W2: Average Score
C3: Game 1 | D3: 27 | E3: 0 | F3: 0 | G3: 68 | H3: 32 | I3: 30 | J3: 0 | K3: 0 | L3: 0 | M3: 32 | N3: 22 | S3: =SUM(D3:R3) -> 211 | T3: =COUNT(D3:R3) -> 11 | U3: =COUNTIF(D3:R3,0) -> 5 | V3: =T3-U3 -> 6 | W3: =S3/V3 -> 35.166667
C4: Game 2 | D4: 27 | E4: 23 | F4: 0 | G4: 31 | H4: 0 | I4: 26 | J4: 34 | K4: 0 | L4: 30 | M4: 33 | S4: =SUM(D4:R4) -> 204 | T4: =COUNT(D4:R4) -> 10 | U4: =COUNTIF(D4:R4,0) -> 3 | V4: =T4-U4 -> 7 | W4: =S4/V4 -> 29.142857
C5: Game 3 | D5: 0 | E5: 0 | F5: 0 | G5: 26 | H5: 29 | I5: 31 | J5: 30 | K5: 28 | L5: 30 | M5: 27 | S5: =SUM(D5:R5) -> 201 | T5: =COUNT(D5:R5) -> 10 | U5: =COUNTIF(D5:R5,0) -> 3 | V5: =T5-U5 -> 7 | W5: =S5/V5 -> 28.714286
C6: Game 4 | D6: 0 | E6: 0 | F6: 30 | G6: 29 | H6: 0 | I6: 0 | J6: 38 | K6: 0 | L6: 32 | M6: 0 | N6: 32 | O6: 0 | P6: 28 | Q6: 37 | S6: =SUM(D6:R6) -> 226 | T6: =COUNT(D6:R6) -> 14 | U6: =COUNTIF(D6:R6,0) -> 7 | V6: =T6-U6 -> 7 | W6: =S6/V6 -> 32.285714
C7: Game 5 | D7: 19 | E7: 0 | F7: 27 | G7: 0 | H7: 0 | I7: 0 | J7: 0 | K7: 0 | L7: 24 | M7: 33 | N7: 0 | O7: 32 | P7: 0 | Q7: 40 | R7: 29 | S7: =SUM(D7:R7) -> 204 | T7: =COUNT(D7:R7) -> 15 | U7: =COUNTIF(D7:R7,0) -> 8 | V7: =T7-U7 -> 7 | W7: =S7/V7 -> 29.142857
C8: Game 6 | D8: 0 | E8: 26 | F8: 23 | G8: 39 | H8: 0 | I8: 26 | J8: 41 | K8: 0 | L8: 30 | M8: 24 | S8: =SUM(D8:R8) -> 209 | T8: =COUNT(D8:R8) -> 10 | U8: =COUNTIF(D8:R8,0) -> 3 | V8: =T8-U8 -> 7 | W8: =S8/V8 -> 29.857143
C9: Game 7 | D9: 0 | E9: 18 | F9: 36 | G9: 23 | H9: 27 | I9: 31 | J9: 31 | K9: 0 | L9: 31 | M9: 30 | S9: =SUM(D9:R9) -> 227 | T9: =COUNT(D9:R9) -> 10 | U9: =COUNTIF(D9:R9,0) -> 2 | V9: =T9-U9 -> 8 | W9: =S9/V9 -> 28.375
C10: Game 8 | D10: 32 | E10: 33 | F10: 0 | G10: 37 | H10: 0 | I10: 32 | J10: 30 | K10: 0 | L10: 25 | M10: 0 | N10: 36 | S10: =SUM(D10:R10) -> 225 | T10: =COUNT(D10:R10) -> 11 | U10: =COUNTIF(D10:R10,0) -> 4 | V10: =T10-U10 -> 7 | W10: =S10/V10 -> 32.142857
C11: Game 9 | D11: 35 | E11: 30 | F11: 30 | G11: 0 | H11: 24 | I11: 34 | J11: 32 | K11: 0 | L11: 32 | S11: =SUM(D11:R11) -> 217 | T11: =COUNT(D11:R11) -> 9 | U11: =COUNTIF(D11:R11,0) -> 2 | V11: =T11-U11 -> 7 | W11: =S11/V11 -> 31
C12: Game 10 | D12: 0 | E12: 0 | F12: 33 | G12: 29 | H12: 34 | I12: 35 | J12: 33 | K12: 30 | L12: 30 | S12: =SUM(D12:R12) -> 224 | T12: =COUNT(D12:R12) -> 9 | U12: =COUNTIF(D12:R12,0) -> 2 | V12: =T12-U12 -> 7 | W12: =S12/V12 -> 32
S13: Averages: | T13: =AVERAGE(T3:T12) -> 10.9 | U13: =AVERAGE(U3:U12) -> 3.9 | V13: =AVERAGE(V3:V12) -> 7 | W13: =AVERAGE(W3:W12) -> 30.782738

Sheet Cumulative Odds 50%
B2: Flip until Cumu Odds < 50% | D2: Round 1 | E2: Round 2 | F2: Round 3 | G2: Round 4 | H2: Round 5 | I2: Round 6 | J2: Round 7 | K2: Round 8 | L2: Round 9 | M2: Round 10 | N2: Round 11 | O2: Round 12 | P2: Round 13 | Q2: Round 14 | R2: Round 15 | S2: Round 16 | T2: Round 17 | U2: Round 18 | V2: Round 19 | W2: Round 20 | X2: Total | Y2: Total Rounds | Z2: Total Busts | AA2: Successes | AB2: Average Score
C3: Game 1 | D3: 37 | E3: 0 | F3: 39 | G3: 31 | H3: 41 | I3: 0 | J3: 37 | K3: 37 | X3: =SUM(D3:W3) -> 222 | Y3: =COUNT(D3:W3) -> 8 | Z3: =COUNTIF(D3:W3,0) -> 2 | AA3: =Y3-Z3 -> 6 | AB3: =X3/AA3 -> 37
C4: Game 2 | D4: 32 | E4: 0 | F4: 0 | G4: 30 | H4: 0 | I4: 29 | J4: 0 | K4: 36 | L4: 0 | M4: 45 | N4: 0 | O4: 34 | X4: =SUM(D4:W4) -> 206 | Y4: =COUNT(D4:W4) -> 12 | Z4: =COUNTIF(D4:W4,0) -> 6 | AA4: =Y4-Z4 -> 6 | AB4: =X4/AA4 -> 34.333333
C5: Game 3 | D5: 0 | E5: 31 | F5: 0 | G5: 0 | H5: 0 | I5: 26 | J5: 37 | K5: 0 | L5: 0 | M5: 0 | N5: 0 | O5: 36 | P5: 0 | Q5: 0 | R5: 0 | S5: 0 | T5: 43 | U5: 0 | V5: 18 | W5: 36 | X5: =SUM(D5:W5) -> 227 | Y5: =COUNT(D5:W5) -> 20 | Z5: =COUNTIF(D5:W5,0) -> 13 | AA5: =Y5-Z5 -> 7 | AB5: =X5/AA5 -> 32.428571
C6: Game 4 | D6: 0 | E6: 0 | F6: 0 | G6: 40 | H6: 34 | I6: 36 | J6: 36 | K6: 0 | L6: 0 | M6: 28 | N6: 0 | O6: 30 | X6: =SUM(D6:W6) -> 204 | Y6: =COUNT(D6:W6) -> 12 | Z6: =COUNTIF(D6:W6,0) -> 6 | AA6: =Y6-Z6 -> 6 | AB6: =X6/AA6 -> 34
C7: Game 5 | D7: 27 | E7: 34 | F7: 45 | G7: 28 | H7: 40 | I7: 0 | J7: 29 | X7: =SUM(D7:W7) -> 203 | Y7: =COUNT(D7:W7) -> 7 | Z7: =COUNTIF(D7:W7,0) -> 1 | AA7: =Y7-Z7 -> 6 | AB7: =X7/AA7 -> 33.833333
C8: Game 6 | D8: 36 | E8: 0 | F8: 33 | G8: 0 | H8: 34 | I8: 36 | J8: 34 | K8: 44 | X8: =SUM(D8:W8) -> 217 | Y8: =COUNT(D8:W8) -> 8 | Z8: =COUNTIF(D8:W8,0) -> 2 | AA8: =Y8-Z8 -> 6 | AB8: =X8/AA8 -> 36.166667
C9: Game 7 | D9: 41 | E9: 0 | F9: 31 | G9: 37 | H9: 0 | I9: 0 | J9: 0 | K9: 0 | L9: 37 | M9: 0 | N9: 0 | O9: 28 | P9: 45 | X9: =SUM(D9:W9) -> 219 | Y9: =COUNT(D9:W9) -> 13 | Z9: =COUNTIF(D9:W9,0) -> 7 | AA9: =Y9-Z9 -> 6 | AB9: =X9/AA9 -> 36.5
C10: Game 8 | D10: 0 | E10: 34 | F10: 37 | G10: 31 | H10: 30 | I10: 40 | J10: 27 | K10: 30 | X10: =SUM(D10:W10) -> 229 | Y10: =COUNT(D10:W10) -> 8 | Z10: =COUNTIF(D10:W10,0) -> 1 | AA10: =Y10-Z10 -> 7 | AB10: =X10/AA10 -> 32.714286
C11: Game 9 | D11: 33 | E11: 0 | F11: 33 | G11: 46 | H11: 41 | I11: 38 | J11: 0 | K11: 32 | X11: =SUM(D11:W11) -> 223 | Y11: =COUNT(D11:W11) -> 8 | Z11: =COUNTIF(D11:W11,0) -> 2 | AA11: =Y11-Z11 -> 6 | AB11: =X11/AA11 -> 37.166667
C12: Game 10 | D12: 42 | E12: 0 | F12: 0 | G12: 0 | H12: 0 | I12: 0 | J12: 37 | K12: 0 | L12: 0 | M12: 0 | N12: 0 | O12: 0 | P12: 39 | Q12: 33 | R12: 40 | S12: 0 | T12: 38 | X12: =SUM(D12:W12) -> 229 | Y12: =COUNT(D12:W12) -> 17 | Z12: =COUNTIF(D12:W12,0) -> 11 | AA12: =Y12-Z12 -> 6 | AB12: =X12/AA12 -> 38.166667
X13: Averages: | Y13: =AVERAGE(Y3:Y12) -> 11.3 | Z13: =AVERAGE(Z3:Z12) -> 5.1 | AA13: =AVERAGE(AA3:AA12) -> 6.2 | AB13: =AVERAGE(AB3:AB12) -> 35.230952

Sheet Cumulative Odds 40%
B2: Flip until Cumu Odds < 40% | D2: Round 1 | E2: Round 2 | F2: Round 3 | G2: Round 4 | H2: Round 5 | I2: Round 6 | J2: Round 7 | K2: Round 8 | L2: Round 9 | M2: Round 10 | N2: Round 11 | O2: Round 12 | P2: Round 13 | Q2: Round 14 | R2: Round 15 | S2: Round 16 | T2: Round 17 | U2: Round 18 | V2: Round 19 | W2: Round 20 | X2: Total | Y2: Total Rounds | Z2: Total Busts | AA2: Successes | AB2: Average Score
C3: Game 1 | D3: 38 | E3: 0 | F3: 0 | G3: 34 | H3: 34 | I3: 0 | J3: 34 | K3: 51 | L3: 37 | X3: =SUM(D3:W3) -> 228 | Y3: =COUNT(D3:W3) -> 9 | Z3: =COUNTIF(D3:W3,0) -> 3 | AA3: =Y3-Z3 -> 6 | AB3: =X3/AA3 -> 38
C4: Game 2 | D4: 0 | E4: 49 | F4: 0 | G4: 0 | H4: 0 | I4: 48 | J4: 46 | K4: 0 | L4: 36 | M4: 0 | N4: 43 | X4: =SUM(D4:W4) -> 222 | Y4: =COUNT(D4:W4) -> 11 | Z4: =COUNTIF(D4:W4,0) -> 6 | AA4: =Y4-Z4 -> 5 | AB4: =X4/AA4 -> 44.4
C5: Game 3 | D5: 0 | E5: 0 | F5: 38 | G5: 33 | H5: 50 | I5: 42 | J5: 0 | K5: 45 | X5: =SUM(D5:W5) -> 208 | Y5: =COUNT(D5:W5) -> 8 | Z5: =COUNTIF(D5:W5,0) -> 3 | AA5: =Y5-Z5 -> 5 | AB5: =X5/AA5 -> 41.6
C6: Game 4 | D6: 0 | E6: 0 | F6: 0 | G6: 37 | H6: 0 | I6: 0 | J6: 36 | K6: 42 | L6: 39 | M6: 39 | N6: 0 | O6: 39 | X6: =SUM(D6:W6) -> 232 | Y6: =COUNT(D6:W6) -> 12 | Z6: =COUNTIF(D6:W6,0) -> 6 | AA6: =Y6-Z6 -> 6 | AB6: =X6/AA6 -> 38.666667
C7: Game 5 | D7: 0 | E7: 0 | F7: 0 | G7: 33 | H7: 0 | I7: 0 | J7: 39 | K7: 0 | L7: 0 | M7: 0 | N7: 0 | O7: 0 | P7: 0 | Q7: 0 | R7: 40 | S7: 0 | T7: 0 | U7: 43 | V7: 40 | W7: 46 | X7: =SUM(D7:W7) -> 241 | Y7: =COUNT(D7:W7) -> 20 | Z7: =COUNTIF(D7:W7,0) -> 14 | AA7: =Y7-Z7 -> 6 | AB7: =X7/AA7 -> 40.166667
C8: Game 6 | D8: 0 | E8: 38 | F8: 41 | G8: 43 | H8: 33 | I8: 0 | J8: 0 | K8: 0 | L8: 64 | X8: =SUM(D8:W8) -> 219 | Y8: =COUNT(D8:W8) -> 9 | Z8: =COUNTIF(D8:W8,0) -> 4 | AA8: =Y8-Z8 -> 5 | AB8: =X8/AA8 -> 43.8
C9: Game 7 | D9: 0 | E9: 35 | F9: 39 | G9: 0 | H9: 0 | I9: 29 | J9: 47 | K9: 37 | L9: 34 | X9: =SUM(D9:W9) -> 221 | Y9: =COUNT(D9:W9) -> 9 | Z9: =COUNTIF(D9:W9,0) -> 3 | AA9: =Y9-Z9 -> 6 | AB9: =X9/AA9 -> 36.833333
C10: Game 8 | D10: 0 | E10: 51 | F10: 0 | G10: 0 | H10: 45 | I10: 50 | J10: 0 | K10: 0 | L10: 32 | M10: 0 | N10: 28 | X10: =SUM(D10:W10) -> 206 | Y10: =COUNT(D10:W10) -> 11 | Z10: =COUNTIF(D10:W10,0) -> 6 | AA10: =Y10-Z10 -> 5 | AB10: =X10/AA10 -> 41.2
C11: Game 9 | D11: 0 | E11: 39 | F11: 34 | G11: 0 | H11: 0 | I11: 0 | J11: 0 | K11: 0 | L11: 49 | M11: 33 | N11: 0 | O11: 0 | P11: 0 | Q11: 0 | R11: 32 | S11: 31 | X11: =SUM(D11:W11) -> 218 | Y11: =COUNT(D11:W11) -> 16 | Z11: =COUNTIF(D11:W11,0) -> 10 | AA11: =Y11-Z11 -> 6 | AB11: =X11/AA11 -> 36.333333
C12: Game 10 | D12: 0 | E12: 45 | F12: 0 | G12: 0 | H12: 0 | I12: 0 | J12: 0 | K12: 0 | L12: 41 | M12: 0 | N12: 0 | O12: 62 | P12: 32 | Q12: 36 | X12: =SUM(D12:W12) -> 216 | Y12: =COUNT(D12:W12) -> 14 | Z12: =COUNTIF(D12:W12,0) -> 9 | AA12: =Y12-Z12 -> 5 | AB12: =X12/AA12 -> 43.2
X13: Averages: | Y13: =AVERAGE(Y3:Y12) -> 11.9 | Z13: =AVERAGE(Z3:Z12) -> 6.4 | AA13: =AVERAGE(AA3:AA12) -> 5.5 | AB13: =AVERAGE(AB3:AB12) -> 40.42

Sheet Cumulative Odds 30%
B2: Flip until Cumu Odds < 30% | D2: Round 1 | E2: Round 2 | F2: Round 3 | G2: Round 4 | H2: Round 5 | I2: Round 6 | J2: Round 7 | K2: Round 8 | L2: Round 9 | M2: Round 10 | N2: Round 11 | O2: Round 12 | P2: Round 13 | Q2: Round 14 | R2: Round 15 | S2: Round 16 | T2: Round 17 | U2: Round 18 | V2: Round 19 | W2: Round 20 | X2: Total | Y2: Total Rounds | Z2: Total Busts | AA2: Successes | AB2: Average Score
C3: Game 1 | D3: 0 | E3: 68 | F3: 0 | G3: 50 | H3: 39 | I3: 40 | J3: 41 | X3: =SUM(D3:W3) -> 238 | Y3: =COUNT(D3:W3) -> 7 | Z3: =COUNTIF(D3:W3,0) -> 2 | AA3: =Y3-Z3 -> 5 | AB3: =X3/AA3 -> 47.6
C4: Game 2 | D4: 42 | E4: 0 | F4: 0 | G4: 42 | H4: 0 | I4: 0 | J4: 0 | K4: 55 | L4: 45 | M4: 0 | N4: 0 | O4: 0 | P4: 0 | Q4: 0 | R4: 0 | S4: 0 | T4: 0 | U4: 0 | V4: 34 | X4: =SUM(D4:W4) -> 218 | Y4: =COUNT(D4:W4) -> 19 | Z4: =COUNTIF(D4:W4,0) -> 14 | AA4: =Y4-Z4 -> 5 | AB4: =X4/AA4 -> 43.6
C5: Game 3 | D5: 41 | E5: 0 | F5: 45 | G5: 0 | H5: 0 | I5: 36 | J5: 35 | K5: 44 | X5: =SUM(D5:W5) -> 201 | Y5: =COUNT(D5:W5) -> 8 | Z5: =COUNTIF(D5:W5,0) -> 3 | AA5: =Y5-Z5 -> 5 | AB5: =X5/AA5 -> 40.2
C6: Game 4 | D6: 43 | E6: 38 | F6: 0 | G6: 50 | H6: 37 | I6: 46 | X6: =SUM(D6:W6) -> 214 | Y6: =COUNT(D6:W6) -> 6 | Z6: =COUNTIF(D6:W6,0) -> 1 | AA6: =Y6-Z6 -> 5 | AB6: =X6/AA6 -> 42.8
C7: Game 5 | D7: 0 | E7: 42 | F7: 0 | G7: 45 | H7: 43 | I7: 0 | J7: 48 | K7: 45 | X7: =SUM(D7:W7) -> 223 | Y7: =COUNT(D7:W7) -> 8 | Z7: =COUNTIF(D7:W7,0) -> 3 | AA7: =Y7-Z7 -> 5 | AB7: =X7/AA7 -> 44.6
C8: Game 6 | D8: 0 | E8: 0 | F8: 0 | G8: 82 | H8: 0 | I8: 46 | J8: 0 | K8: 42 | L8: 0 | M8: 39 | X8: =SUM(D8:W8) -> 209 | Y8: =COUNT(D8:W8) -> 10 | Z8: =COUNTIF(D8:W8,0) -> 6 | AA8: =Y8-Z8 -> 4 | AB8: =X8/AA8 -> 52.25
C9: Game 7 | D9: 0 | E9: 0 | F9: 0 | G9: 0 | H9: 39 | I9: 37 | J9: 44 | K9: 42 | L9: 51 | X9: =SUM(D9:W9) -> 213 | Y9: =COUNT(D9:W9) -> 9 | Z9: =COUNTIF(D9:W9,0) -> 4 | AA9: =Y9-Z9 -> 5 | AB9: =X9/AA9 -> 42.6
C10: Game 8 | D10: 39 | E10: 0 | F10: 0 | G10: 37 | H10: 0 | I10: 0 | J10: 0 | K10: 0 | L10: 33 | M10: 0 | N10: 0 | O10: 0 | P10: 0 | Q10: 40 | R10: 0 | S10: 51 | X10: =SUM(D10:W10) -> 200 | Y10: =COUNT(D10:W10) -> 16 | Z10: =COUNTIF(D10:W10,0) -> 11 | AA10: =Y10-Z10 -> 5 | AB10: =X10/AA10 -> 40
C11: Game 9 | D11: 0 | E11: 40 | F11: 38 | G11: 0 | H11: 0 | I11: 0 | J11: 0 | K11: 0 | L11: 45 | M11: 46 | N11: 0 | O11: 39 | X11: =SUM(D11:W11) -> 208 | Y11: =COUNT(D11:W11) -> 12 | Z11: =COUNTIF(D11:W11,0) -> 7 | AA11: =Y11-Z11 -> 5 | AB11: =X11/AA11 -> 41.6
C12: Game 10 | D12: 45 | E12: 46 | F12: 45 | G12: 0 | H12: 51 | I12: 0 | J12: 0 | K12: 0 | L12: 54 | X12: =SUM(D12:W12) -> 241 | Y12: =COUNT(D12:W12) -> 9 | Z12: =COUNTIF(D12:W12,0) -> 4 | AA12: =Y12-Z12 -> 5 | AB12: =X12/AA12 -> 48.2
X13: Averages: | Y13: =AVERAGE(Y3:Y12) -> 10.4 | Z13: =AVERAGE(Z3:Z12) -> 5.5 | AA13: =AVERAGE(AA3:AA12) -> 4.9 | AB13: =AVERAGE(AB3:AB12) -> 44.345

Sheet Individual Odds 10%
B2: Flip until Individual Odds > 10% | D2: Round 1 | E2: Round 2 | F2: Round 3 | G2: Round 4 | H2: Round 5 | I2: Round 6 | J2: Round 7 | K2: Round 8 | L2: Round 9 | M2: Round 10 | N2: Round 11 | O2: Round 12 | P2: Round 13 | Q2: Round 14 | R2: Round 15 | S2: Round 16 | T2: Round 17 | U2: Round 18 | V2: Round 19 | W2: Round 20 | X2: Total | Y2: Total Rounds | Z2: Total Busts | AA2: Successes | AB2: Average Score
C3: Game 1 | D3: 13 | E3: 13 | F3: 11 | G3: 11 | H3: 10 | I3: 12 | J3: 13 | K3: 20 | L3: 16 | M3: 20 | N3: 23 | O3: 15 | P3: 58 | X3: =SUM(D3:W3) -> 235 | Y3: =COUNT(D3:W3) -> 13 | Z3: =COUNTIF(D3:W3,0) -> 0 | AA3: =Y3-Z3 -> 13 | AB3: =X3/AA3 -> 18.076923
C4: Game 2 | D4: 13 | E4: 0 | F4: 11 | G4: 0 | H4: 22 | I4: 11 | J4: 12 | K4: 14 | L4: 14 | M4: 12 | N4: 13 | O4: 10 | P4: 22 | Q4: 10 | R4: 12 | S4: 12 | T4: 15 | X4: =SUM(D4:W4) -> 203 | Y4: =COUNT(D4:W4) -> 17 | Z4: =COUNTIF(D4:W4,0) -> 2 | AA4: =Y4-Z4 -> 15 | AB4: =X4/AA4 -> 13.533333
C5: Game 3 | D5: 30 | E5: 22 | F5: 11 | G5: 11 | H5: 15 | I5: 17 | J5: 16 | K5: 17 | L5: 18 | M5: 17 | N5: 11 | O5: 20 | X5: =SUM(D5:W5) -> 205 | Y5: =COUNT(D5:W5) -> 12 | Z5: =COUNTIF(D5:W5,0) -> 0 | AA5: =Y5-Z5 -> 12 | AB5: =X5/AA5 -> 17.083333
C6: Game 4 | D6: 11 | E6: 10 | F6: 16 | G6: 0 | H6: 23 | I6: 12 | J6: 13 | K6: 14 | L6: 15 | M6: 17 | N6: 12 | O6: 16 | P6: 11 | Q6: 12 | R6: 13 | S6: 13 | X6: =SUM(D6:W6) -> 208 | Y6: =COUNT(D6:W6) -> 16 | Z6: =COUNTIF(D6:W6,0) -> 1 | AA6: =Y6-Z6 -> 15 | AB6: =X6/AA6 -> 13.866667
C7: Game 5 | D7: 12 | E7: 10 | F7: 12 | G7: 19 | H7: 19 | I7: 11 | J7: 12 | K7: 12 | L7: 0 | M7: 13 | N7: 19 | O7: 16 | P7: 17 | Q7: 11 | R7: 11 | S7: 12 | X7: =SUM(D7:W7) -> 206 | Y7: =COUNT(D7:W7) -> 16 | Z7: =COUNTIF(D7:W7,0) -> 1 | AA7: =Y7-Z7 -> 15 | AB7: =X7/AA7 -> 13.733333
C8: Game 6 | D8: 13 | E8: 12 | F8: 51 | G8: 16 | H8: 12 | I8: 13 | J8: 12 | K8: 11 | L8: 13 | M8: 14 | N8: 12 | O8: 13 | P8: 13 | X8: =SUM(D8:W8) -> 205 | Y8: =COUNT(D8:W8) -> 13 | Z8: =COUNTIF(D8:W8,0) -> 0 | AA8: =Y8-Z8 -> 13 | AB8: =X8/AA8 -> 15.769231
C9: Game 7 | D9: 12 | E9: 14 | F9: 18 | G9: 10 | H9: 18 | I9: 14 | J9: 18 | K9: 12 | L9: 15 | M9: 9 | N9: 15 | O9: 12 | P9: 22 | Q9: 12 | X9: =SUM(D9:W9) -> 201 | Y9: =COUNT(D9:W9) -> 14 | Z9: =COUNTIF(D9:W9,0) -> 0 | AA9: =Y9-Z9 -> 14 | AB9: =X9/AA9 -> 14.357143
C10: Game 8 | D10: 13 | E10: 24 | F10: 15 | G10: 10 | H10: 12 | I10: 15 | J10: 13 | K10: 0 | L10: 13 | M10: 15 | N10: 18 | O10: 18 | P10: 14 | Q10: 15 | R10: 14 | S10: 9 | X10: =SUM(D10:W10) -> 218 | Y10: =COUNT(D10:W10) -> 16 | Z10: =COUNTIF(D10:W10,0) -> 1 | AA10: =Y10-Z10 -> 15 | AB10: =X10/AA10 -> 14.533333
C11: Game 9 | D11: 13 | E11: 22 | F11: 14 | G11: 10 | H11: 0 | I11: 17 | J11: 16 | K11: 13 | L11: 15 | M11: 12 | N11: 13 | O11: 12 | P11: 18 | Q11: 17 | R11: 15 | X11: =SUM(D11:W11) -> 207 | Y11: =COUNT(D11:W11) -> 15 | Z11: =COUNTIF(D11:W11,0) -> 1 | AA11: =Y11-Z11 -> 14 | AB11: =X11/AA11 -> 14.785714
C12: Game 10 | D12: 13 | E12: 10 | F12: 11 | G12: 12 | H12: 16 | I12: 11 | J12: 20 | K12: 19 | L12: 13 | M12: 23 | N12: 18 | O12: 21 | P12: 17 | X12: =SUM(D12:W12) -> 204 | Y12: =COUNT(D12:W12) -> 13 | Z12: =COUNTIF(D12:W12,0) -> 0 | AA12: =Y12-Z12 -> 13 | AB12: =X12/AA12 -> 15.692308
X13: Averages: | Y13: =AVERAGE(Y3:Y12) -> 14.5 | Z13: =AVERAGE(Z3:Z12) -> 0.6 | AA13: =AVERAGE(AA3:AA12) -> 13.9 | AB13: =AVERAGE(AB3:AB12) -> 15.143132

Sheet Individual Odds 20%
B2: Flip until Individual Odds > 20% | D2: Round 1 | E2: Round 2 | F2: Round 3 | G2: Round 4 | H2: Round 5 | I2: Round 6 | J2: Round 7 | K2: Round 8 | L2: Round 9 | M2: Round 10 | N2: Round 11 | O2: Round 12 | P2: Round 13 | Q2: Round 14 | R2: Round 15 | S2: Total | T2: Total Rounds | U2: Total Busts | V2: Successes | W2: Average Score
C3: Game 1 | D3: 0 | E3: 23 | F3: 0 | G3: 28 | H3: 31 | I3: 26 | J3: 30 | K3: 0 | L3: 23 | M3: 0 | N3: 40 | S3: =SUM(D3:R3) -> 201 | T3: =COUNT(D3:R3) -> 11 | U3: =COUNTIF(D3:R3,0) -> 4 | V3: =T3-U3 -> 7 | W3: =S3/V3 -> 28.714286
C4: Game 2 | D4: 20 | E4: 30 | F4: 30 | G4: 0 | H4: 24 | I4: 21 | J4: 24 | K4: 0 | L4: 0 | M4: 33 | N4: 24 | S4: =SUM(D4:R4) -> 206 | T4: =COUNT(D4:R4) -> 11 | U4: =COUNTIF(D4:R4,0) -> 3 | V4: =T4-U4 -> 8 | W4: =S4/V4 -> 25.75
C5: Game 3 | D5: 26 | E5: 23 | F5: 31 | G5: 22 | H5: 37 | I5: 22 | J5: 33 | K5: 52 | S5: =SUM(D5:R5) -> 246 | T5: =COUNT(D5:R5) -> 8 | U5: =COUNTIF(D5:R5,0) -> 0 | V5: =T5-U5 -> 8 | W5: =S5/V5 -> 30.75
C6: Game 4 | D6: 28 | E6: 22 | F6: 21 | G6: 23 | H6: 23 | I6: 29 | J6: 31 | K6: 21 | L6: 24 | S6: =SUM(D6:R6) -> 222 | T6: =COUNT(D6:R6) -> 9 | U6: =COUNTIF(D6:R6,0) -> 0 | V6: =T6-U6 -> 9 | W6: =S6/V6 -> 24.666667
C7: Game 5 | D7: 25 | E7: 0 | F7: 0 | G7: 21 | H7: 0 | I7: 21 | J7: 31 | K7: 0 | L7: 0 | M7: 23 | N7: 19 | O7: 25 | P7: 22 | Q7: 24 | S7: =SUM(D7:R7) -> 211 | T7: =COUNT(D7:R7) -> 14 | U7: =COUNTIF(D7:R7,0) -> 5 | V7: =T7-U7 -> 9 | W7: =S7/V7 -> 23.444444
C8: Game 6 | D8: 22 | E8: 23 | F8: 22 | G8: 28 | H8: 23 | I8: 0 | J8: 37 | K8: 0 | L8: 22 | S8: =SUM(D8:R8) -> 177 | T8: =COUNT(D8:R8) -> 9 | U8: =COUNTIF(D8:R8,0) -> 2 | V8: =T8-U8 -> 7 | W8: =S8/V8 -> 25.285714
C9: Game 7 | D9: 21 | E9: 0 | F9: 28 | G9: 0 | H9: 27 | I9: 24 | J9: 0 | K9: 25 | L9: 26 | M9: 24 | N9: 23 | O9: 24 | S9: =SUM(D9:R9) -> 222 | T9: =COUNT(D9:R9) -> 12 | U9: =COUNTIF(D9:R9,0) -> 3 | V9: =T9-U9 -> 9 | W9: =S9/V9 -> 24.666667
C10: Game 8 | D10: 30 | E10: 25 | F10: 24 | G10: 21 | H10: 34 | I10: 28 | J10: 23 | K10: 23 | S10: =SUM(D10:R10) -> 208 | T10: =COUNT(D10:R10) -> 8 | U10: =COUNTIF(D10:R10,0) -> 0 | V10: =T10-U10 -> 8 | W10: =S10/V10 -> 26
C11: Game 9 | D11: 0 | E11: 26 | F11: 25 | G11: 31 | H11: 0 | I11: 30 | J11: 29 | K11: 34 | L11: 0 | M11: 24 | N11: 0 | O11: 23 | S11: =SUM(D11:R11) -> 222 | T11: =COUNT(D11:R11) -> 12 | U11: =COUNTIF(D11:R11,0) -> 4 | V11: =T11-U11 -> 8 | W11: =S11/V11 -> 27.75
C12: Game 10 | D12: 23 | E12: 24 | F12: 27 | G12: 24 | H12: 0 | I12: 24 | J12: 18 | K12: 28 | L12: 0 | M12: 27 | N12: 25 | S12: =SUM(D12:R12) -> 220 | T12: =COUNT(D12:R12) -> 11 | U12: =COUNTIF(D12:R12,0) -> 2 | V12: =T12-U12 -> 9 | W12: =S12/V12 -> 24.444444
S13: Averages: | T13: =AVERAGE(T3:T12) -> 10.5 | U13: =AVERAGE(U3:U12) -> 2.3 | V13: =AVERAGE(V3:V12) -> 8.2 | W13: =AVERAGE(W3:W12) -> 26.147222

Sheet Individual Odds 30%
